Workbook

Sheet Resumo Servico
A1: PRICING - SQUAD AS A SERVICE (HITZ) - MODELO POR SERVICO
A3: PREMISSAS GERAIS
A4: Margem alvo (cota, antes do IR) | B4: 0.38 | D4: Margem objetivo sobre o faturamento
A5: SG&A | B5: 0.1 | D5: Despesas administrativas/comerciais
A6: ISS | B6: 0.02 | D6: Imposto sobre servicos
A7: PIS | B7: 0.0065 | D7: Regime cumulativo
A8: COFINS | B8: 0.03 | D8: Regime cumulativo
A9: Custo financeiro (mensal) | B9: 0.025 | D9: Capital de giro - 1 mes financiado
A10: IRPJ/CSLL | B10: 0.34 | D10: Apenas para DRE (nao afeta o preco)
A11: Vigencia do contrato (meses) | B11: 3 | D11: Minimo contratual conforme proposta
A12: Horas/mes por FTE | B12: 160 | D12: Base para preco/hora implicito
A13: IA por FTE/mes (R$) | B13: 500 | D13: Tokens/seats Cursor, Claude, etc.
A14: Software/licencas por pessoa/mes (R$) | B14: 900 | D14: Ferramentas por pessoa
A15: Equipamento por pessoa (R$, CAPEX) | B15: 6000 | D15: Amortizado pela vida util
A16: Vida util equipamento (meses) | B16: 24 | D16: Amortizacao do CAPEX
A18: COMPOSICAO DO TIME
A19: Papel | B19: Salario (R$) | C19: Alocacao | D19: Qtd Prop. 1 | E19: Qtd Prop. 2
A20: AI Product Manager | B20: 18000 | C20: 0.5 | D20: 1 | E20: 1
A21: Product Builder Pleno | B21: 15000 | C21: 1 | D21: 1 | E21: 2
A22: Product Builder Junior | B22: 11000 | C22: 1 | D22: 1 | E22: 1
A23: Pessoas (headcount) | D23: =SUM(D20:D22) -> 3 | E23: =SUM(E20:E22) -> 4
A24: FTE-equivalente | D24: =SUMPRODUCT(C20:C22,D20:D22) -> 2.5 | E24: =SUMPRODUCT(C20:C22,E20:E22) -> 3.5
A26: CUSTO E PRECO POR PROPOSTA
B27: PROPOSTA 1 (Comercial) | C27: PROPOSTA 2 (Estendida)
A28: Custo pessoas/mes | B28: =SUMPRODUCT($B$20:$B$22,$C$20:$C$22,$D$20:$D$22) -> 35000 | C28: =SUMPRODUCT($B$20:$B$22,$C$20:$C$22,$E$20:$E$22) -> 50000
A29: FTE-equivalente | B29: =$D$24 -> 2.5 | C29: =$E$24 -> 3.5
A30: Pessoas (headcount) | B30: =$D$23 -> 3 | C30: =$E$23 -> 4
A31: (+) IA / tokens | B31: =B29*$B$13 -> 1250 | C31: =C29*$B$13 -> 1750
A32: (+) Software / licencas | B32: =B30*$B$14 -> 2700 | C32: =C30*$B$14 -> 3600
A33: (+) Equipamento (amortizado) | B33: =B30*$B$15/$B$16 -> 750 | C33: =C30*$B$15/$B$16 -> 1000
A34: (+) Cloud / infra | B34: 0 | C34: 0
A35: Total adicionais/mes | B35: =SUM(B31:B34) -> 4700 | C35: =SUM(C31:C34) -> 6350
A36: CUSTO DELIVERY / MES | B36: =B28+B35 -> 39700 | C36: =C28+C35 -> 56350
A38: Custo delivery total (vigencia) | B38: =B36*$B$11 -> 119100 | C38: =C36*$B$11 -> 169050
A39: (+) Custo financeiro | B39: =B36*$B$9 -> 992.5 | C39: =C36*$B$9 -> 1408.75
A40: Custos totais | B40: =B38+B39 -> 120092.5 | C40: =C38+C39 -> 170458.75
A41: Divisor gross-up | B41: =1-$B$6-$B$7-$B$8-$B$5-$B$4 -> 0.4635 | C41: =1-$B$6-$B$7-$B$8-$B$5-$B$4 -> 0.4635
A42: Faturamento total (vigencia) | B42: =B40/B41 -> 259099.24 | C42: =C40/C41 -> 367764.29
A43: PRECO MENSAL (FIDEDIGNO) | B43: =B42/$B$11 -> 86366.415 | C43: =C42/$B$11 -> 122588.1
A44: Preco/hora implicito | B44: =B43/(B29*$B$12) -> 215.91604 | C44: =C43/(C29*$B$12) -> 218.90732
...

Sheet P&L
A1: P&L - SQUAD AS A SERVICE (HITZ)
A3: Em R$ (total da vigencia) | B3: Proposta 1 (Comercial) | C3: Proposta 2 (Estendida)
A4: Faturamento (Receita Bruta) | B4: ='Resumo Servico'!B42 -> 259099.24 | C4: ='Resumo Servico'!C42 -> 367764.29
A5: (-) ISS | B5: =-B4*'Resumo Servico'!$B$6 -> -5181.9849 | C5: =-C4*'Resumo Servico'!$B$6 -> -7355.2859
A6: (-) PIS | B6: =-B4*'Resumo Servico'!$B$7 -> -1684.1451 | C6: =-C4*'Resumo Servico'!$B$7 -> -2390.4679
A7: (-) COFINS | B7: =-B4*'Resumo Servico'!$B$8 -> -7772.9773 | C7: =-C4*'Resumo Servico'!$B$8 -> -11032.929
A8: Receita Liquida | B8: =B4+B5+B6+B7 -> 244460.14 | C8: =C4+C5+C6+C7 -> 346985.61
A9: (-) Custo Delivery | B9: =-'Resumo Servico'!B38 -> -119100 | C9: =-'Resumo Servico'!C38 -> -169050
A10: (-) Custo Financeiro | B10: =-'Resumo Servico'!B39 -> -992.5 | C10: =-'Resumo Servico'!C39 -> -1408.75
A11: Margem Bruta | B11: =B8+B9+B10 -> 124367.64 | C11: =C8+C9+C10 -> 176526.86
A12: (-) SG&A | B12: =-'Resumo Servico'!$B$5*B4 -> -25909.924 | C12: =-'Resumo Servico'!$B$5*C4 -> -36776.429
A13: LAIR (Lucro Antes do IR) | B13: =B11+B12 -> 98457.713 | C13: =C11+C12 -> 139750.43
A14: (-) IRPJ/CSLL | B14: =IF(B13>0,-B13*'Resumo Servico'!$B$10,0) -> -33475.622 | C14: =IF(C13>0,-C13*'Resumo Servico'!$B$10,0) -> -47515.147
A15: Lucro Liquido | B15: =B13+B14 -> 64982.091 | C15: =C13+C14 -> 92235.285
A16: % Margem Liquida | B16: =B15/B4 -> 0.2508 | C16: =C15/C4 -> 0.2508
A18: MEMO
A19: Preco mensal (fidedigno) | B19: ='Resumo Servico'!B43 -> 86366.415 | C19: ='Resumo Servico'!C43 -> 122588.1
A20: Vigencia (meses) | B20: ='Resumo Servico'!$B$11 -> 3 | C20: ='Resumo Servico'!$B$11 -> 3
A21: Total do contrato | B21: =B4 -> 259099.24 | C21: =C4 -> 367764.29

Sheet Proposta Comercial
A1: PROPOSTA COMERCIAL - SQUAD AS A SERVICE (HITZ)
A3: # | B3: Descricao | C3: Unidade | D3: Qtd (meses) | E3: Valor mensal (R$) | F3: Valor total contrato (R$)
A4: 1 | B4: Squad as a Service - Comercial 1 AI Product Manager + 2 Product Builders | Seg-Sex, 09h-18h (Brasilia) | C4: mes | D4: ='Resumo Servico'!$B$11 -> 3 | E4: ='Resumo Servico'!B43 -> 86366.415 | F4: =D4*E4 -> 259099.24
A5: 2 | B5: Squad as a Service - Cobertura Estendida 1 AI Product Manager + 3 Product Builders (1 em cobertura estendida) | inclui noites, sabados e domingos | C5: mes | D5: ='Resumo Servico'!$B$11 -> 3 | E5: ='Resumo Servico'!C43 -> 122588.1 | F5: =D5*E5 -> 367764.29
A7: Condicoes (conforme proposta):
A8: - Contratacao minima de 3 meses. Valores mensais, sem custos de setup.
A9: - Product Builder adicional sob demanda, mediante aviso previo de 15 dias.
A10: - Squad dedicado: prioriza, estima em Ponto de Funcao e entrega em ciclos continuos.
A11: - SLAs de sustentacao (N1/N2/N3) conforme matriz de severidade da proposta.
