Workbook

Sheet Capa
D2: Planilha de Contagem de Pontos de Função - Versão 2025.01
E3: Roteiro de Métricas de Software do SISP V.2.3
B4: Identificação da Contagem
C6: Projeto/Demanda | D6: Riple - Fase 4
C8: Aplicação | D8: Riple - Ferramenta de Gestão de Desenvolvimento
C10: Responsável | D10: Prodesp
C12: Tipo de Contagem | D12: Projeto de Desenvolvimento
C14: Forma de Contagem | D14: Detalhada
B16: Tamanho em Pontos de Função
B17: Pontos de Função (IFPUG) | E17: =SUM('Deflatores Sisp'!$J$4:$J$38) -> 105
B18: Manutenção Corretiva (Legado ou S/ Garantia) | E18: =SUMIF('Deflatores Sisp'!$M$4:$M$38,"CORRETIVA",'Deflatores Sisp'!$K$4:$K$38) -> 0
B19: Manutenção Adaptativa | E19: =SUMIF('Deflatores Sisp'!$M$4:$M$38,"ADAPTATIVA",'Deflatores Sisp'!$K$4:$K$38) -> 0
B20: Melhoria Evolutiva - Func. Incluídas | E20: =SUMIF('Deflatores Sisp'!$M$4:$M$38,"EvolutivaI",'Deflatores Sisp'!$K$4:$K$38) -> 105
B21: Melhoria Evolutiva - Func. Alteradas | E21: =SUMIF('Deflatores Sisp'!$M$4:$M$38,"EvolutivaA",'Deflatores Sisp'!$K$4:$K$38) -> 0
B22: Melhoria Evolutiva - Func. Excluídas | E22: =SUMIF('Deflatores Sisp'!$M$4:$M$38,"EvolutivaE",'Deflatores Sisp'!$K$4:$K$38) -> 0
B23: Tamanho Funcional Ajustado | E23: ='Deflatores Sisp'!N2 -> 99.75
B24: Requisitos Técnicos (Correlação com Guia Local) | E24: =SUM('Deflatores Sisp'!$K$42:$K$70) -> 0
B25: Total Pontos de Função (Tamanho Funcional Ajustado + Requisitos Não Funcionais) | E25: ='Funções'!O6 -> 99.75
B27: Escopo geral da contagem
B28: Planilha para controle das medições do Riple Fase 4 (Sustentação e Evolução)
B32: Histórico do Documento
B33: Data | C33: Versão | D33: Descrição | E33: Autor
B34: 45978 | C34: 1.0 | D34: Criação da planilha e inclusão das contagens das Sprints iniciais para entrada em produção do Sistema | E34: Levi Barros Nóbrega

Sheet Funções
A1: Planilha de contagem de ponto de função - Versão 1.0
A4: ='Capa'!C6&" : "&'Capa'!D6 -> Projeto/Demanda : Riple - Fase 4 | C4: ='Capa'!C12&" : "&'Capa'!D12 -> Tipo de Contagem : Projeto de Desenvolvimento
A5: ='Capa'!C8&" : "&'Capa'!D8 -> Aplicação : Riple - Ferramenta de Gestão de Desenvolvimento | C5: ='Capa'!C14&" : "&'Capa'!D14 -> Forma de Contagem : Detalhada | K5: Total PF IFPUG | N5: PF Local do EM | O5: Total PF Ajustado | P5: Fases/Disciplinas
A6: ='Capa'!C10&" : "&'Capa'!D10 -> Responsável : Prodesp | K6: =SUM($K$8:$K$121694) -> 105 | N6: =SUM($N$8:$N$110) -> 105 | O6: 99.75
A7: Medição / Sprint / Tarefa | B7: Detalhes / Nome da Função | C7: Tipo | D7: Manutenção | E7: TD | F7: Descr TD | G7: AR/TR | H7: Descr AR/TR | I7: Complex. | J7: ctl | K7: PF IFPUG | L7: C | M7: ctl2 | N7: PF Local do EM | O7: PF Ajustado | P7: Requisitos (25%) | Q7: Projeto (10%) | R7: Implementação (40%) | S7: Teste (15%) | T7: Homologação (5%) | U7: Implantação (5%) | V7: Não se aplica | W7: % Percentual por Disciplina | X7: Referência | Y7: Observações
A8: Medição 04 (M04) | B8: Tarefas da Medição 04 - Fevereiro/2026 | I8: =IF(ISBLANK(C8),"",IF(L8="L","Baixa",IF(L8="A","Média",IF(L8="","","Alta")))) | J8: =CONCATENATE(C8,L8) | K8: =IF(ISBLANK(C8),"",IF(C8="ALI",IF(L8="L",7,IF(L8="A",10,15)),IF(C8="AIE",IF(L8="L",5,IF(L8="A",7,10)),IF(C8="SE",IF(L8="L",4,IF(L8="A",5,7)),IF(OR(C8="EE",C8="CE"),IF(L8="L",3,IF(L8="A",4,6)),0))))) | L8: =IF(OR(ISBLANK(E8),ISBLANK(G8)),IF(OR(C8="ALI",C8="AIE"),"L",IF(OR(C8="EE",C8="SE",C8="CE"),"A","")),IF(C8="EE",IF(G8>=3,IF(E8>=5,"H","A"),IF(G8>=2,IF(E8>=16,"H",IF(E8<=4,"L","A")),IF(E8<=15,"L","A"))),IF(OR(C8="SE",C8="CE"),IF(G8>=4,IF(E8>=6,"H","A"),IF(G8>=2,IF(E8>=20,"H",IF(E8<=5,"L","A")),IF(E8<=19,"L","A"))),IF(OR(C8="ALI",C8="AIE"),IF(G8>=6,IF(E8>=20,"H","A"),IF(G8>=2,IF(E8>=51,"H",IF(E8<=19,"L","A")),IF(E8<=50,"L","A"))),"")))) | M8: =CONCATENATE(C8,D8) | N8: =IF(OR(K8="",K8=0),O8,K8) | O8: =_xlfn.IFERROR(IF(NOT(ISERROR(VLOOKUP(C8,'Deflatores Sisp'!G$42:H$70,2,FALSE))),VLOOKUP(C8,'Deflatores Sisp'!G$42:H$70,2,FALSE),IF(OR(ISBLANK(D8),ISBLANK(C8)),"",VLOOKUP(D8,'Deflatores Sisp'!G$4:H$38,2,FALSE)*K8+VLOOKUP(D8,'Deflatores Sisp'!G$4:I$38,3,FALSE)))*W8,"") | W8: =IF(V8="",SUM(Z8:AE8),IF(C8="PA",E8,100%)) -> 0 | Z8: =IF(P8="x",25%,0) -> 0 | AA8: =IF(Q8="x",10%,0) -> 0 | AB8: =IF(R8="x",40%,0) -> 0 | AC8: =IF(S8="x",15%,0) -> 0 | AD8: =IF(T8="x",5%,0) -> 0 | AE8: =IF(U8="x",5%,0) -> 0
A9: M04 | B9: Tarefas do Sprint 04, de 20/01/2026 a 13/02/2026 | I9: =IF(ISBLANK(C9),"",IF(L9="L","Baixa",IF(L9="A","Média",IF(L9="","","Alta")))) | J9: =CONCATENATE(C9,L9) | K9: =IF(ISBLANK(C9),"",IF(C9="ALI",IF(L9="L",7,IF(L9="A",10,15)),IF(C9="AIE",IF(L9="L",5,IF(L9="A",7,10)),IF(C9="SE",IF(L9="L",4,IF(L9="A",5,7)),IF(OR(C9="EE",C9="CE"),IF(L9="L",3,IF(L9="A",4,6)),0))))) | L9: =IF(OR(ISBLANK(E9),ISBLANK(G9)),IF(OR(C9="ALI",C9="AIE"),"L",IF(OR(C9="EE",C9="SE",C9="CE"),"A","")),IF(C9="EE",IF(G9>=3,IF(E9>=5,"H","A"),IF(G9>=2,IF(E9>=16,"H",IF(E9<=4,"L","A")),IF(E9<=15,"L","A"))),IF(OR(C9="SE",C9="CE"),IF(G9>=4,IF(E9>=6,"H","A"),IF(G9>=2,IF(E9>=20,"H",IF(E9<=5,"L","A")),IF(E9<=19,"L","A"))),IF(OR(C9="ALI",C9="AIE"),IF(G9>=6,IF(E9>=20,"H","A"),IF(G9>=2,IF(E9>=51,"H",IF(E9<=19,"L","A")),IF(E9<=50,"L","A"))),"")))) | M9: =CONCATENATE(C9,D9) | N9: =IF(OR(K9="",K9=0),O9,K9) | O9: =_xlfn.IFERROR(IF(NOT(ISERROR(VLOOKUP(C9,'Deflatores Sisp'!G$42:H$70,2,FALSE))),VLOOKUP(C9,'Deflatores Sisp'!G$42:H$70,2,FALSE),IF(OR(ISBLANK(D9),ISBLANK(C9)),"",VLOOKUP(D9,'Deflatores Sisp'!G$4:H$38,2,FALSE)*K9+VLOOKUP(D9,'Deflatores Sisp'!G$4:I$38,3,FALSE)))*W9,"") | W9: =IF(V9="",SUM(Z9:AE9),IF(C9="PA",E9,100%)) -> 0 | Z9: =IF(P9="x",25%,0) -> 0 | AA9: =IF(Q9="x",10%,0) -> 0 | AB9: =IF(R9="x",40%,0) -> 0 | AC9: =IF(S9="x",15%,0) -> 0 | AD9: =IF(T9="x",5%,0) -> 0 | AE9: =IF(U9="x",5%,0) -> 0
B10: Listar_OSs_Migraveis_HHPF | C10: CE | D10: I | E10: 12 | F10: os_numero, projeto_nome, cliente_nome, fornecedor_razao_social, contrato_codigo, tipo_os_atual, pf_saldo_disponivel, horas_totais, total_itens, itens_migraveis, status_vigencia, filtros_contrato_fornecedor_status. Listagem paginada de Ordens de Serviço do tipo HH/PF elegíveis para migração manual para o tipo PF, exibidas na tela administrativa de Migração HH/PF → PF. | G10: 5 | H10: 5 TR: (1) Ordens_Servico – dados principais da OS candidata à migração; (2) Contratos – código e parâmetros contratuais do contrato base; (3) Projetos – nome do projeto e cliente vinculado; (4) Fornecedores – razão social do fornecedor responsável pela OS; (5) Itens_OS – contagem de itens elegíveis para conversão por OS. | I10: =IF(ISBLANK(C10),"",IF(L10="L","Baixa",IF(L10="A","Média",IF(L10="","","Alta")))) -> Alta | J10: =CONCATENATE(C10,L10) -> CEH | K10: =IF(ISBLANK(C10),"",IF(C10="ALI",IF(L10="L",7,IF(L10="A",10,15)),IF(C10="AIE",IF(L10="L",5,IF(L10="A",7,10)),IF(C10="SE",IF(L10="L",4,IF(L10="A",5,7)),IF(OR(C10="EE",C10="CE"),IF(L10="L",3,IF(L10="A",4,6)),0))))) -> 6 | L10: =IF(OR(ISBLANK(E10),ISBLANK(G10)),IF(OR(C10="ALI",C10="AIE"),"L",IF(OR(C10="EE",C10="SE",C10="CE"),"A","")),IF(C10="EE",IF(G10>=3,IF(E10>=5,"H","A"),IF(G10>=2,IF(E10>=16,"H",IF(E10<=4,"L","A")),IF(E10<=15,"L","A"))),IF(OR(C10="SE",C10="CE"),IF(G10>=4,IF(E10>=6,"H","A"),IF(G10>=2,IF(E10>=20,"H",IF(E10<=5,"L","A")),IF(E10<=19,"L","A"))),IF(OR(C10="ALI",C10="AIE"),IF(G10>=6,IF(E10>=20,"H","A"),IF(G10>=2,IF(E10>=51,"H",IF(E10<=19,"L","A")),IF(E10<=50,"L","A"))),"")))) -> H | M10: =CONCATENATE(C10,D10) -> CEI | N10: =IF(OR(K10="",K10=0),O10,K10) -> 6 | O10: =_xlfn.IFERROR(IF(NOT(ISERROR(VLOOKUP(C10,'Deflatores Sisp'!G$42:H$70,2,FALSE))),VLOOKUP(C10,'Deflatores Sisp'!G$42:H$70,2,FALSE),IF(OR(ISBLANK(D10),ISBLANK(C10)),"",VLOOKUP(D10,'Deflatores Sisp'!G$4:H$38,2,FALSE)*K10+VLOOKUP(D10,'Deflatores Sisp'!G$4:I$38,3,FALSE)))*W10,"") -> 5.7 | P10: x | Q10: x | R10: x | S10: x | U10: x | W10: =IF(V10="",SUM(Z10:AE10),IF(C10="PA",E10,100%)) -> 0.95 | Z10: =IF(P10="x",25%,0) -> 0.25 | AA10: =IF(Q10="x",10%,0) -> 0.1 | AB10: =IF(R10="x",40%,0) -> 0.4 | AC10: =IF(S10="x",15%,0) -> 0.15 | AD10: =IF(T10="x",5%,0) -> 0 | AE10: =IF(U10="x",5%,0) -> 0.05
B11: Detalhe_OS_Para_Migracao_HHPF | C11: CE | D11: I | E11: 14 | F11: os_numero, projeto_nome, cliente_nome, contrato_codigo, tipo_os_atual, pf_total, pf_consumido, pf_saldo, horas_totais_origem, itens_completos[], itens_incompletos[], ates_sem_perfil[], perfis_contrato_map, valor_por_perfil, pf_rate_resolvido. Visualização detalhada de uma OS HH/PF antes da migração, exibindo header, itens elegíveis, ATEs sem perfil vinculado e impacto previsto item a item. | G11: 6 | H11: 6 TR: (1) Ordens_Servico – header completo da OS em migração; (2) Itens_OS – itens HST/UST vigentes para conversão; (3) Itens_Contrato – parâmetros de preço e perfil por item; (4) Usuarios_e_Papeis – profiles de ATEs vinculados à OS; (5) Apontamentos – histórico de consumo por item; (6) Apontamento_PF_Movimentos – movimentações auditoria PF. | I11: =IF(ISBLANK(C11),"",IF(L11="L","Baixa",IF(L11="A","Média",IF(L11="","","Alta")))) -> Alta | J11: =CONCATENATE(C11,L11) -> CEH | K11: =IF(ISBLANK(C11),"",IF(C11="ALI",IF(L11="L",7,IF(L11="A",10,15)),IF(C11="AIE",IF(L11="L",5,IF(L11="A",7,10)),IF(C11="SE",IF(L11="L",4,IF(L11="A",5,7)),IF(OR(C11="EE",C11="CE"),IF(L11="L",3,IF(L11="A",4,6)),0))))) -> 6 | L11: =IF(OR(ISBLANK(E11),ISBLANK(G11)),IF(OR(C11="ALI",C11="AIE"),"L",IF(OR(C11="EE",C11="SE",C11="CE"),"A","")),IF(C11="EE",IF(G11>=3,IF(E11>=5,"H","A"),IF(G11>=2,IF(E11>=16,"H",IF(E11<=4,"L","A")),IF(E11<=15,"L","A"))),IF(OR(C11="SE",C11="CE"),IF(G11>=4,IF(E11>=6,"H","A"),IF(G11>=2,IF(E11>=20,"H",IF(E11<=5,"L","A")),IF(E11<=19,"L","A"))),IF(OR(C11="ALI",C11="AIE"),IF(G11>=6,IF(E11>=20,"H","A"),IF(G11>=2,IF(E11>=51,"H",IF(E11<=19,"L","A")),IF(E11<=50,"L","A"))),"")))) -> H | M11: =CONCATENATE(C11,D11) -> CEI | N11: =IF(OR(K11="",K11=0),O11,K11) -> 6 | O11: =_xlfn.IFERROR(IF(NOT(ISERROR(VLOOKUP(C11,'Deflatores Sisp'!G$42:H$70,2,FALSE))),VLOOKUP(C11,'Deflatores Sisp'!G$42:H$70,2,FALSE),IF(OR(ISBLANK(D11),ISBLANK(C11)),"",VLOOKUP(D11,'Deflatores Sisp'!G$4:H$38,2,FALSE)*K11+VLOOKUP(D11,'Deflatores Sisp'!G$4:I$38,3,FALSE)))*W11,"") -> 5.7 | P11: x | Q11: x | R11: x | S11: x | U11: x | W11: =IF(V11="",SUM(Z11:AE11),IF(C11="PA",E11,100%)) -> 0.95 | Z11: =IF(P11="x",25%,0) -> 0.25 | AA11: =IF(Q11="x",10%,0) -> 0.1 | AB11: =IF(R11="x",40%,0) -> 0.4 | AC11: =IF(S11="x",15%,0) -> 0.15 | AD11: =IF(T11="x",5%,0) -> 0 | AE11: =IF(U11="x",5%,0) -> 0.05
B12: Preview_DryRun_Migracao_Item_HHPF | C12: SE | D12: I | E12: 12 | F12: item_os_id, item_contrato_origem, item_contrato_destino_pf, apontamentos_livres_count, horas_livres, pf_equivalente_preview, pf_saldo_antes, pf_saldo_depois, validacoes_bloqueantes[], validacoes_informativas[], perfil_ate_esperado, impacto_valor_total. Geração de preview (dry-run) da migração de um item HH/PF para o item PF correspondente do mesmo contrato, sem persistir dados, permitindo ao administrador conferir o impacto antes da execução. | G12: 5 | H12: 5 TR: (1) Itens_OS – item origem a ser convertido; (2) Itens_Contrato – mapeamento origem→PF no mesmo contrato; (3) Apontamentos – apontamentos livres sem período fechado; (4) Usuarios_e_Papeis – perfis ATE envolvidos no cálculo; (5) Ordens_Servico – saldo PF simulado pós-migração. | I12: =IF(ISBLANK(C12),"",IF(L12="L","Baixa",IF(L12="A","Média",IF(L12="","","Alta")))) -> Alta | J12: =CONCATENATE(C12,L12) -> SEH | K12: =IF(ISBLANK(C12),"",IF(C12="ALI",IF(L12="L",7,IF(L12="A",10,15)),IF(C12="AIE",IF(L12="L",5,IF(L12="A",7,10)),IF(C12="SE",IF(L12="L",4,IF(L12="A",5,7)),IF(OR(C12="EE",C12="CE"),IF(L12="L",3,IF(L12="A",4,6)),0))))) -> 7 | L12: =IF(OR(ISBLANK(E12),ISBLANK(G12)),IF(OR(C12="ALI",C12="AIE"),"L",IF(OR(C12="EE",C12="SE",C12="CE"),"A","")),IF(C12="EE",IF(G12>=3,IF(E12>=5,"H","A"),IF(G12>=2,IF(E12>=16,"H",IF(E12<=4,"L","A")),IF(E12<=15,"L","A"))),IF(OR(C12="SE",C12="CE"),IF(G12>=4,IF(E12>=6,"H","A"),IF(G12>=2,IF(E12>=20,"H",IF(E12<=5,"L","A")),IF(E12<=19,"L","A"))),IF(OR(C12="ALI",C12="AIE"),IF(G12>=6,IF(E12>=20,"H","A"),IF(G12>=2,IF(E12>=51,"H",IF(E12<=19,"L","A")),IF(E12<=50,"L","A"))),"")))) -> H | M12: =CONCATENATE(C12,D12) -> SEI | N12: =IF(OR(K12="",K12=0),O12,K12) -> 7 | O12: =_xlfn.IFERROR(IF(NOT(ISERROR(VLOOKUP(C12,'Deflatores Sisp'!G$42:H$70,2,FALSE))),VLOOKUP(C12,'Deflatores Sisp'!G$42:H$70,2,FALSE),IF(OR(ISBLANK(D12),ISBLANK(C12)),"",VLOOKUP(D12,'Deflatores Sisp'!G$4:H$38,2,FALSE)*K12+VLOOKUP(D12,'Deflatores Sisp'!G$4:I$38,3,FALSE)))*W12,"") -> 6.65 | P12: x | Q12: x | R12: x | S12: x | U12: x | W12: =IF(V12="",SUM(Z12:AE12),IF(C12="PA",E12,100%)) -> 0.95 | Z12: =IF(P12="x",25%,0) -> 0.25 | AA12: =IF(Q12="x",10%,0) -> 0.1 | AB12: =IF(R12="x",40%,0) -> 0.4 | AC12: =IF(S12="x",15%,0) -> 0.15 | AD12: =IF(T12="x",5%,0) -> 0 | AE12: =IF(U12="x",5%,0) -> 0.05
B13: Confirmar_Migracao_Item_HHPF_Para_PF | C13: EE | D13: I | E13: 10 | F13: item_os_id, item_contrato_destino_pf, confirmado_por, confirmado_em, pf_saldo_anterior, pf_saldo_novo, apontamentos_afetados[], recalculo_disparado, audit_log_id, dry_run_flag. Execução efetiva da migração de um item HH/PF para o item PF correspondente, com recálculo automático do saldo PF da OS via hhpf_recalc_pf_saldo_os e registro em audit_logs. | G13: 5 | H13: 5 TR: (1) Itens_OS – troca de item_contrato_id para versão PF; (2) Ordens_Servico – saldo PF recalculado automaticamente; (3) Apontamento_PF_Movimentos – registro de movimento auditoria; (4) Audit_Logs – log detalhado da operação administrativa; (5) Profiles – identificação do administrador executor. | I13: =IF(ISBLANK(C13),"",IF(L13="L","Baixa",IF(L13="A","Média",IF(L13="","","Alta")))) -> Alta | J13: =CONCATENATE(C13,L13) -> EEH | K13: =IF(ISBLANK(C13),"",IF(C13="ALI",IF(L13="L",7,IF(L13="A",10,15)),IF(C13="AIE",IF(L13="L",5,IF(L13="A",7,10)),IF(C13="SE",IF(L13="L",4,IF(L13="A",5,7)),IF(OR(C13="EE",C13="CE"),IF(L13="L",3,IF(L13="A",4,6)),0))))) -> 6 | L13: =IF(OR(ISBLANK(E13),ISBLANK(G13)),IF(OR(C13="ALI",C13="AIE"),"L",IF(OR(C13="EE",C13="SE",C13="CE"),"A","")),IF(C13="EE",IF(G13>=3,IF(E13>=5,"H","A"),IF(G13>=2,IF(E13>=16,"H",IF(E13<=4,"L","A")),IF(E13<=15,"L","A"))),IF(OR(C13="SE",C13="CE"),IF(G13>=4,IF(E13>=6,"H","A"),IF(G13>=2,IF(E13>=20,"H",IF(E13<=5,"L","A")),IF(E13<=19,"L","A"))),IF(OR(C13="ALI",C13="AIE"),IF(G13>=6,IF(E13>=20,"H","A"),IF(G13>=2,IF(E13>=51,"H",IF(E13<=19,"L","A")),IF(E13<=50,"L","A"))),"")))) -> H | M13: =CONCATENATE(C13,D13) -> EEI | N13: =IF(OR(K13="",K13=0),O13,K13) -> 6 | O13: =_xlfn.IFERROR(IF(NOT(ISERROR(VLOOKUP(C13,'Deflatores Sisp'!G$42:H$70,2,FALSE))),VLOOKUP(C13,'Deflatores Sisp'!G$42:H$70,2,FALSE),IF(OR(ISBLANK(D13),ISBLANK(C13)),"",VLOOKUP(D13,'Deflatores Sisp'!G$4:H$38,2,FALSE)*K13+VLOOKUP(D13,'Deflatores Sisp'!G$4:I$38,3,FALSE)))*W13,"") -> 5.7 | P13: x | Q13: x | R13: x | S13: x | U13: x | W13: =IF(V13="",SUM(Z13:AE13),IF(C13="PA",E13,100%)) -> 0.95 | Z13: =IF(P13="x",25%,0) -> 0.25 | AA13: =IF(Q13="x",10%,0) -> 0.1 | AB13: =IF(R13="x",40%,0) -> 0.4 | AC13: =IF(S13="x",15%,0) -> 0.15 | AD13: =IF(T13="x",5%,0) -> 0 | AE13: =IF(U13="x",5%,0) -> 0.05
B14: Preservacao_Itens_OS_Ao_Trocar_Tipo | C14: EE | D14: I | E14: 10 | F14: os_id, tipo_os_anterior, tipo_os_novo, itens_preservados[], quantidades_mantidas, alocacoes_mantidas, categoria_item_determinada, itens_incompativeis_removidos[], alterado_por, alterado_em. Preservação automática de quantidades e alocações de itens ao alternar entre tipos de OS compatíveis (ex.: HORAS ↔ HH/PF ↔ PROVISORIA_PF) no formulário de Ordem de Serviço, com utilitário de determinação de categoria do item para decidir o que manter ou descartar. | G14: 4 | H14: 4 TR: (1) Ordens_Servico – atualização de tipo_os com contexto preservado; (2) Itens_OS – retenção de quantidades e perfil_contrato_id; (3) Colaborador_Item_OS – manutenção das alocações ATE→item; (4) Itens_Contrato – validação de categoria compatível item a item. | I14: =IF(ISBLANK(C14),"",IF(L14="L","Baixa",IF(L14="A","Média",IF(L14="","","Alta")))) -> Alta | J14: =CONCATENATE(C14,L14) -> EEH | K14: =IF(ISBLANK(C14),"",IF(C14="ALI",IF(L14="L",7,IF(L14="A",10,15)),IF(C14="AIE",IF(L14="L",5,IF(L14="A",7,10)),IF(C14="SE",IF(L14="L",4,IF(L14="A",5,7)),IF(OR(C14="EE",C14="CE"),IF(L14="L",3,IF(L14="A",4,6)),0))))) -> 6 | L14: =IF(OR(ISBLANK(E14),ISBLANK(G14)),IF(OR(C14="ALI",C14="AIE"),"L",IF(OR(C14="EE",C14="SE",C14="CE"),"A","")),IF(C14="EE",IF(G14>=3,IF(E14>=5,"H","A"),IF(G14>=2,IF(E14>=16,"H",IF(E14<=4,"L","A")),IF(E14<=15,"L","A"))),IF(OR(C14="SE",C14="CE"),IF(G14>=4,IF(E14>=6,"H","A"),IF(G14>=2,IF(E14>=20,"H",IF(E14<=5,"L","A")),IF(E14<=19,"L","A"))),IF(OR(C14="ALI",C14="AIE"),IF(G14>=6,IF(E14>=20,"H","A"),IF(G14>=2,IF(E14>=51,"H",IF(E14<=19,"L","A")),IF(E14<=50,"L","A"))),"")))) -> H | M14: =CONCATENATE(C14,D14) -> EEI | N14: =IF(OR(K14="",K14=0),O14,K14) -> 6 | O14: =_xlfn.IFERROR(IF(NOT(ISERROR(VLOOKUP(C14,'Deflatores Sisp'!G$42:H$70,2,FALSE))),VLOOKUP(C14,'Deflatores Sisp'!G$42:H$70,2,FALSE),IF(OR(ISBLANK(D14),ISBLANK(C14)),"",VLOOKUP(D14,'Deflatores Sisp'!G$4:H$38,2,FALSE)*K14+VLOOKUP(D14,'Deflatores Sisp'!G$4:I$38,3,FALSE)))*W14,"") -> 5.7 | P14: x | Q14: x | R14: x | S14: x | U14: x | W14: =IF(V14="",SUM(Z14:AE14),IF(C14="PA",E14,100%)) -> 0.95 | Z14: =IF(P14="x",25%,0) -> 0.25 | AA14: =IF(Q14="x",10%,0) -> 0.1 | AB14: =IF(R14="x",40%,0) -> 0.4 | AC14: =IF(S14="x",15%,0) -> 0.15 | AD14: =IF(T14="x",5%,0) -> 0 | AE14: =IF(U14="x",5%,0) -> 0.05
B15: Resolver_Taxa_PF_Dominancia_Estrita | C15: AIE | D15: I | E15: 20 | F15: os_id, ate_id, data_referencia, contrato_id, perfil_contrato_id, pf_rate_dominante, fonte_calculo, candidatos_considerados[], peso_por_candidato, score_dominancia, scenario_fallback_aplicado, estrategia_usada, pf_rate_legacy, heuristica_version, display_rate_resolvido, valor_documento_oficial_ref, horas_contabilizadas, pf_convertido_preview, divergencia_detectada, log_auditoria_resolucao. Função RPC hhpf_resolve_pf_rate de resolução de taxa PF com heurística de dominância estrita para cenários multi-perfil, substituindo lógica antiga por algoritmo determinístico que preserva integridade histórica, aplica fallback controlado e loga decisão de resolução para auditoria contábil. | G15: 4 | H15: 4 TR: (1) Itens_Contrato – taxas PF por perfil no contrato; (2) Usuarios_e_Papeis – perfil_contrato_id ativo do ATE; (3) Ordens_Servico – tipo/escopo da OS origem; (4) Apontamentos – contexto histórico para fallback. | I15: =IF(ISBLANK(C15),"",IF(L15="L","Baixa",IF(L15="A","Média",IF(L15="","","Alta")))) -> Média | J15: =CONCATENATE(C15,L15) -> AIEA | K15: =IF(ISBLANK(C15),"",IF(C15="ALI",IF(L15="L",7,IF(L15="A",10,15)),IF(C15="AIE",IF(L15="L",5,IF(L15="A",7,10)),IF(C15="SE",IF(L15="L",4,IF(L15="A",5,7)),IF(OR(C15="EE",C15="CE"),IF(L15="L",3,IF(L15="A",4,6)),0))))) -> 7 | L15: =IF(OR(ISBLANK(E15),ISBLANK(G15)),IF(OR(C15="ALI",C15="AIE"),"L",IF(OR(C15="EE",C15="SE",C15="CE"),"A","")),IF(C15="EE",IF(G15>=3,IF(E15>=5,"H","A"),IF(G15>=2,IF(E15>=16,"H",IF(E15<=4,"L","A")),IF(E15<=15,"L","A"))),IF(OR(C15="SE",C15="CE"),IF(G15>=4,IF(E15>=6,"H","A"),IF(G15>=2,IF(E15>=20,"H",IF(E15<=5,"L","A")),IF(E15<=19,"L","A"))),IF(OR(C15="ALI",C15="AIE"),IF(G15>=6,IF(E15>=20,"H","A"),IF(G15>=2,IF(E15>=51,"H",IF(E15<=19,"L","A")),IF(E15<=50,"L","A"))),"")))) -> A | M15: =CONCATENATE(C15,D15) -> AIEI | N15: =IF(OR(K15="",K15=0),O15,K15) -> 7 | O15: =_xlfn.IFERROR(IF(NOT(ISERROR(VLOOKUP(C15,'Deflatores Sisp'!G$42:H$70,2,FALSE))),VLOOKUP(C15,'Deflatores Sisp'!G$42:H$70,2,FALSE),IF(OR(ISBLANK(D15),ISBLANK(C15)),"",VLOOKUP(D15,'Deflatores Sisp'!G$4:H$38,2,FALSE)*K15+VLOOKUP(D15,'Deflatores Sisp'!G$4:I$38,3,FALSE)))*W15,"") -> 6.65 | P15: x | Q15: x | R15: x | S15: x | U15: x | W15: =IF(V15="",SUM(Z15:AE15),IF(C15="PA",E15,100%)) -> 0.95 | Z15: =IF(P15="x",25%,0) -> 0.25 | AA15: =IF(Q15="x",10%,0) -> 0.1 | AB15: =IF(R15="x",40%,0) -> 0.4 | AC15: =IF(S15="x",15%,0) -> 0.15 | AD15: =IF(T15="x",5%,0) -> 0 | AE15: =IF(U15="x",5%,0) -> 0.05
B16: Calendario_Apontamentos_Fornecedor | C16: CE | D16: I | E16: 14 | F16: data_referencia, total_horas_dia, total_registros_dia, status_list[], ates_distintos, color_coded_status, filtros_data_inicio_fim, filtros_ate, filtros_os, filtros_status, tooltip_resumo, navegacao_mensal, drill_down_detalhado, agregacao_automatica. Visualização em formato de calendário dos apontamentos agregados por dia dos ATEs do fornecedor autenticado, com filtros por ATE, OS e status, substituindo visualização de lista em Histórico de Apontamentos do Fornecedor. | G16: 6 | H16: 6 TR: (1) Apontamentos – registros horários agregados por dia; (2) Usuarios_e_Papeis – ATEs do fornecedor autenticado; (3) Fornecedores – escopo de visibilidade do gestor; (4) Ordens_Servico – filtro por OS específica; (5) Profiles – fornecedor_id do usuário autenticado; (6) Periodos_Mensais – range padrão de consulta. | I16: =IF(ISBLANK(C16),"",IF(L16="L","Baixa",IF(L16="A","Média",IF(L16="","","Alta")))) -> Alta | J16: =CONCATENATE(C16,L16) -> CEH | K16: =IF(ISBLANK(C16),"",IF(C16="ALI",IF(L16="L",7,IF(L16="A",10,15)),IF(C16="AIE",IF(L16="L",5,IF(L16="A",7,10)),IF(C16="SE",IF(L16="L",4,IF(L16="A",5,7)),IF(OR(C16="EE",C16="CE"),IF(L16="L",3,IF(L16="A",4,6)),0))))) -> 6 | L16: =IF(OR(ISBLANK(E16),ISBLANK(G16)),IF(OR(C16="ALI",C16="AIE"),"L",IF(OR(C16="EE",C16="SE",C16="CE"),"A","")),IF(C16="EE",IF(G16>=3,IF(E16>=5,"H","A"),IF(G16>=2,IF(E16>=16,"H",IF(E16<=4,"L","A")),IF(E16<=15,"L","A"))),IF(OR(C16="SE",C16="CE"),IF(G16>=4,IF(E16>=6,"H","A"),IF(G16>=2,IF(E16>=20,"H",IF(E16<=5,"L","A")),IF(E16<=19,"L","A"))),IF(OR(C16="ALI",C16="AIE"),IF(G16>=6,IF(E16>=20,"H","A"),IF(G16>=2,IF(E16>=51,"H",IF(E16<=19,"L","A")),IF(E16<=50,"L","A"))),"")))) -> H | M16: =CONCATENATE(C16,D16) -> CEI | N16: =IF(OR(K16="",K16=0),O16,K16) -> 6 | O16: =_xlfn.IFERROR(IF(NOT(ISERROR(VLOOKUP(C16,'Deflatores Sisp'!G$42:H$70,2,FALSE))),VLOOKUP(C16,'Deflatores Sisp'!G$42:H$70,2,FALSE),IF(OR(ISBLANK(D16),ISBLANK(C16)),"",VLOOKUP(D16,'Deflatores Sisp'!G$4:H$38,2,FALSE)*K16+VLOOKUP(D16,'Deflatores Sisp'!G$4:I$38,3,FALSE)))*W16,"") -> 5.7 | P16: x | Q16: x | R16: x | S16: x | U16: x | W16: =IF(V16="",SUM(Z16:AE16),IF(C16="PA",E16,100%)) -> 0.95 | Z16: =IF(P16="x",25%,0) -> 0.25 | AA16: =IF(Q16="x",10%,0) -> 0.1 | AB16: =IF(R16="x",40%,0) -> 0.4 | AC16: =IF(S16="x",15%,0) -> 0.15 | AD16: =IF(T16="x",5%,0) -> 0 | AE16: =IF(U16="x",5%,0) -> 0.05
B17: Exportar_Calendario_Excel_Fornecedor | C17: SE | D17: I | E17: 12 | F17: data_referencia, ate_nome, ate_matricula, os_numero, projeto_nome, hora_entrada, hora_saida, total_horas, status_apontamento, atividades, horas_extras, horas_banco, data_exportacao, filtros_aplicados. Exportação para Excel do detalhamento de apontamentos do calendário do fornecedor, com linhas por apontamento e colunas padronizadas para conferência contábil. | G17: 5 | H17: 5 TR: (1) Apontamentos – linhas detalhadas a exportar; (2) Usuarios_e_Papeis – nome e matrícula dos ATEs; (3) Ordens_Servico – número da OS apontada; (4) Projetos – nome do projeto vinculado; (5) Fornecedores – escopo fornecedor do usuário. | I17: =IF(ISBLANK(C17),"",IF(L17="L","Baixa",IF(L17="A","Média",IF(L17="","","Alta")))) -> Alta | J17: =CONCATENATE(C17,L17) -> SEH | K17: =IF(ISBLANK(C17),"",IF(C17="ALI",IF(L17="L",7,IF(L17="A",10,15)),IF(C17="AIE",IF(L17="L",5,IF(L17="A",7,10)),IF(C17="SE",IF(L17="L",4,IF(L17="A",5,7)),IF(OR(C17="EE",C17="CE"),IF(L17="L",3,IF(L17="A",4,6)),0))))) -> 7 | L17: =IF(OR(ISBLANK(E17),ISBLANK(G17)),IF(OR(C17="ALI",C17="AIE"),"L",IF(OR(C17="EE",C17="SE",C17="CE"),"A","")),IF(C17="EE",IF(G17>=3,IF(E17>=5,"H","A"),IF(G17>=2,IF(E17>=16,"H",IF(E17<=4,"L","A")),IF(E17<=15,"L","A"))),IF(OR(C17="SE",C17="CE"),IF(G17>=4,IF(E17>=6,"H","A"),IF(G17>=2,IF(E17>=20,"H",IF(E17<=5,"L","A")),IF(E17<=19,"L","A"))),IF(OR(C17="ALI",C17="AIE"),IF(G17>=6,IF(E17>=20,"H","A"),IF(G17>=2,IF(E17>=51,"H",IF(E17<=19,"L","A")),IF(E17<=50,"L","A"))),"")))) -> H | M17: =CONCATENATE(C17,D17) -> SEI | N17: =IF(OR(K17="",K17=0),O17,K17) -> 7 | O17: =_xlfn.IFERROR(IF(NOT(ISERROR(VLOOKUP(C17,'Deflatores Sisp'!G$42:H$70,2,FALSE))),VLOOKUP(C17,'Deflatores Sisp'!G$42:H$70,2,FALSE),IF(OR(ISBLANK(D17),ISBLANK(C17)),"",VLOOKUP(D17,'Deflatores Sisp'!G$4:H$38,2,FALSE)*K17+VLOOKUP(D17,'Deflatores Sisp'!G$4:I$38,3,FALSE)))*W17,"") -> 6.65 | P17: x | Q17: x | R17: x | S17: x | U17: x | W17: =IF(V17="",SUM(Z17:AE17),IF(C17="PA",E17,100%)) -> 0.95 | Z17: =IF(P17="x",25%,0) -> 0.25 | AA17: =IF(Q17="x",10%,0) -> 0.1 | AB17: =IF(R17="x",40%,0) -> 0.4 | AC17: =IF(S17="x",15%,0) -> 0.15 | AD17: =IF(T17="x",5%,0) -> 0 | AE17: =IF(U17="x",5%,0) -> 0.05
B18: Tipo_OS_PROVISORIA_PF | C18: EE | D18: I | E18: 12 | F18: os_id, tipo_os, numero_nullable, itens_pf_provisorios[], horas_totais_provisorias, pf_saldo_provisorio, perfil_contrato_obrigatorio, vigencia_provisoria_inicio, vigencia_provisoria_fim, criado_por, observacoes, flag_aguardando_numero_oficial. Inclusão do tipo de OS 'PROVISORIA_PF' no formulário e validações, permitindo criar OS PF antes do número oficial ser atribuído pelo cliente, com numero nullable e transição controlada para PF definitivo. | G18: 5 | H18: 5 TR: (1) Ordens_Servico – novo tipo_os aceito por check constraint; (2) Itens_OS – itens provisórios vinculados; (3) Itens_Contrato – perfis PF disponíveis no contrato; (4) Parametros_Contratuais – regras do contrato origem; (5) Profiles – criador do registro provisório. | I18: =IF(ISBLANK(C18),"",IF(L18="L","Baixa",IF(L18="A","Média",IF(L18="","","Alta")))) -> Alta | J18: =CONCATENATE(C18,L18) -> EEH | K18: =IF(ISBLANK(C18),"",IF(C18="ALI",IF(L18="L",7,IF(L18="A",10,15)),IF(C18="AIE",IF(L18="L",5,IF(L18="A",7,10)),IF(C18="SE",IF(L18="L",4,IF(L18="A",5,7)),IF(OR(C18="EE",C18="CE"),IF(L18="L",3,IF(L18="A",4,6)),0))))) -> 6 | L18: =IF(OR(ISBLANK(E18),ISBLANK(G18)),IF(OR(C18="ALI",C18="AIE"),"L",IF(OR(C18="EE",C18="SE",C18="CE"),"A","")),IF(C18="EE",IF(G18>=3,IF(E18>=5,"H","A"),IF(G18>=2,IF(E18>=16,"H",IF(E18<=4,"L","A")),IF(E18<=15,"L","A"))),IF(OR(C18="SE",C18="CE"),IF(G18>=4,IF(E18>=6,"H","A"),IF(G18>=2,IF(E18>=20,"H",IF(E18<=5,"L","A")),IF(E18<=19,"L","A"))),IF(OR(C18="ALI",C18="AIE"),IF(G18>=6,IF(E18>=20,"H","A"),IF(G18>=2,IF(E18>=51,"H",IF(E18<=19,"L","A")),IF(E18<=50,"L","A"))),"")))) -> H | M18: =CONCATENATE(C18,D18) -> EEI | N18: =IF(OR(K18="",K18=0),O18,K18) -> 6 | O18: =_xlfn.IFERROR(IF(NOT(ISERROR(VLOOKUP(C18,'Deflatores Sisp'!G$42:H$70,2,FALSE))),VLOOKUP(C18,'Deflatores Sisp'!G$42:H$70,2,FALSE),IF(OR(ISBLANK(D18),ISBLANK(C18)),"",VLOOKUP(D18,'Deflatores Sisp'!G$4:H$38,2,FALSE)*K18+VLOOKUP(D18,'Deflatores Sisp'!G$4:I$38,3,FALSE)))*W18,"") -> 5.7 | P18: x | Q18: x | R18: x | S18: x | U18: x | W18: =IF(V18="",SUM(Z18:AE18),IF(C18="PA",E18,100%)) -> 0.95 | Z18: =IF(P18="x",25%,0) -> 0.25 | AA18: =IF(Q18="x",10%,0) -> 0.1 | AB18: =IF(R18="x",40%,0) -> 0.4 | AC18: =IF(S18="x",15%,0) -> 0.15 | AD18: =IF(T18="x",5%,0) -> 0 | AE18: =IF(U18="x",5%,0) -> 0.05
B19: Conversao_PROVISORIA_Para_PF_Definitiva | C19: EE | D19: I | E19: 10 | F19: os_id, numero_oficial_novo, data_conversao, valor_oficial, horas_totais_reconsolidadas, pf_total_consolidado, apontamentos_preservados, documentos_revinculados, convertido_por, justificativa. Operação de conversão de uma OS PROVISORIA_PF em PF definitiva quando o número oficial é disponibilizado, preservando itens, apontamentos e saldo consumido, com recálculo de totalizadores. | G19: 5 | H19: 5 TR: (1) Ordens_Servico – atualização do tipo e número oficial; (2) Itens_OS – reconciliação dos itens PF; (3) Apontamentos – revinculação para o novo contexto; (4) Documento_Periodo_Status – atualização dos documentos gerados; (5) Audit_Logs – auditoria da conversão definitiva. | I19: =IF(ISBLANK(C19),"",IF(L19="L","Baixa",IF(L19="A","Média",IF(L19="","","Alta")))) -> Alta | J19: =CONCATENATE(C19,L19) -> EEH | K19: =IF(ISBLANK(C19),"",IF(C19="ALI",IF(L19="L",7,IF(L19="A",10,15)),IF(C19="AIE",IF(L19="L",5,IF(L19="A",7,10)),IF(C19="SE",IF(L19="L",4,IF(L19="A",5,7)),IF(OR(C19="EE",C19="CE"),IF(L19="L",3,IF(L19="A",4,6)),0))))) -> 6 | L19: =IF(OR(ISBLANK(E19),ISBLANK(G19)),IF(OR(C19="ALI",C19="AIE"),"L",IF(OR(C19="EE",C19="SE",C19="CE"),"A","")),IF(C19="EE",IF(G19>=3,IF(E19>=5,"H","A"),IF(G19>=2,IF(E19>=16,"H",IF(E19<=4,"L","A")),IF(E19<=15,"L","A"))),IF(OR(C19="SE",C19="CE"),IF(G19>=4,IF(E19>=6,"H","A"),IF(G19>=2,IF(E19>=20,"H",IF(E19<=5,"L","A")),IF(E19<=19,"L","A"))),IF(OR(C19="ALI",C19="AIE"),IF(G19>=6,IF(E19>=20,"H","A"),IF(G19>=2,IF(E19>=51,"H",IF(E19<=19,"L","A")),IF(E19<=50,"L","A"))),"")))) -> H | M19: =CONCATENATE(C19,D19) -> EEI | N19: =IF(OR(K19="",K19=0),O19,K19) -> 6 | O19: =_xlfn.IFERROR(IF(NOT(ISERROR(VLOOKUP(C19,'Deflatores Sisp'!G$42:H$70,2,FALSE))),VLOOKUP(C19,'Deflatores Sisp'!G$42:H$70,2,FALSE),IF(OR(ISBLANK(D19),ISBLANK(C19)),"",VLOOKUP(D19,'Deflatores Sisp'!G$4:H$38,2,FALSE)*K19+VLOOKUP(D19,'Deflatores Sisp'!G$4:I$38,3,FALSE)))*W19,"") -> 5.7 | P19: x | Q19: x | R19: x | S19: x | U19: x | W19: =IF(V19="",SUM(Z19:AE19),IF(C19="PA",E19,100%)) -> 0.95 | Z19: =IF(P19="x",25%,0) -> 0.25 | AA19: =IF(Q19="x",10%,0) -> 0.1 | AB19: =IF(R19="x",40%,0) -> 0.4 | AC19: =IF(S19="x",15%,0) -> 0.15 | AD19: =IF(T19="x",5%,0) -> 0 | AE19: =IF(U19="x",5%,0) -> 0.05
B20: Conversao_HH_Para_PF_RN02 | C20: EE | D20: I | E20: 12 | F20: os_id, periodo_faturamento_id, apontamentos_agregados[], total_horas_periodo, pf_convertido_bruto, pf_convertido_truncado, valor_documento_oficial, rates_ate_aplicadas, perfis_por_ate[], deducao_automatica_saldo, divergencia_tratada, rn02_versao_aplicada. Motor de conversão HH→PF alinhado à RN02, englobando cálculo determinístico com rates ATE, dedução automática do saldo PF, truncamento contábil e reconciliação com valor documento oficial no faturamento de OSs HH/PF. | G20: 5 | H20: 5 TR: (1) Apontamentos – horas-fonte do período; (2) Usuarios_e_Papeis – perfis ATE resolvidos por apontamento; (3) Itens_Contrato – rates PF do contrato; (4) Ordens_Servico – saldo PF deduzido automaticamente; (5) Periodos_Faturamento – escopo temporal de cálculo. | I20: =IF(ISBLANK(C20),"",IF(L20="L","Baixa",IF(L20="A","Média",IF(L20="","","Alta")))) -> Alta | J20: =CONCATENATE(C20,L20) -> EEH | K20: =IF(ISBLANK(C20),"",IF(C20="ALI",IF(L20="L",7,IF(L20="A",10,15)),IF(C20="AIE",IF(L20="L",5,IF(L20="A",7,10)),IF(C20="SE",IF(L20="L",4,IF(L20="A",5,7)),IF(OR(C20="EE",C20="CE"),IF(L20="L",3,IF(L20="A",4,6)),0))))) -> 6 | L20: =IF(OR(ISBLANK(E20),ISBLANK(G20)),IF(OR(C20="ALI",C20="AIE"),"L",IF(OR(C20="EE",C20="SE",C20="CE"),"A","")),IF(C20="EE",IF(G20>=3,IF(E20>=5,"H","A"),IF(G20>=2,IF(E20>=16,"H",IF(E20<=4,"L","A")),IF(E20<=15,"L","A"))),IF(OR(C20="SE",C20="CE"),IF(G20>=4,IF(E20>=6,"H","A"),IF(G20>=2,IF(E20>=20,"H",IF(E20<=5,"L","A")),IF(E20<=19,"L","A"))),IF(OR(C20="ALI",C20="AIE"),IF(G20>=6,IF(E20>=20,"H","A"),IF(G20>=2,IF(E20>=51,"H",IF(E20<=19,"L","A")),IF(E20<=50,"L","A"))),"")))) -> H | M20: =CONCATENATE(C20,D20) -> EEI | N20: =IF(OR(K20="",K20=0),O20,K20) -> 6 | O20: =_xlfn.IFERROR(IF(NOT(ISERROR(VLOOKUP(C20,'Deflatores Sisp'!G$42:H$70,2,FALSE))),VLOOKUP(C20,'Deflatores Sisp'!G$42:H$70,2,FALSE),IF(OR(ISBLANK(D20),ISBLANK(C20)),"",VLOOKUP(D20,'Deflatores Sisp'!G$4:H$38,2,FALSE)*K20+VLOOKUP(D20,'Deflatores Sisp'!G$4:I$38,3,FALSE)))*W20,"") -> 5.7 | P20: x | Q20: x | R20: x | S20: x | U20: x | W20: =IF(V20="",SUM(Z20:AE20),IF(C20="PA",E20,100%)) -> 0.95 | Z20: =IF(P20="x",25%,0) -> 0.25 | AA20: =IF(Q20="x",10%,0) -> 0.1 | AB20: =IF(R20="x",40%,0) -> 0.4 | AC20: =IF(S20="x",15%,0) -> 0.15 | AD20: =IF(T20="x",5%,0) -> 0 | AE20: =IF(U20="x",5%,0) -> 0.05
B21: Apontamento_Pos_Fechamento_Insercao | C21: EE | D21: I | E21: 10 | F21: apontamento_id, periodo_id, pos_fechamento_flag, data_referencia, horas_regulares, horas_extras, horas_banco, justificativa_pos_fechamento, autorizado_por, autorizado_em, trigger_validacao_aplicada. Inserção, edição e transferência de apontamentos marcados como 'pós-fechamento' em períodos de faturamento já fechados, com trigger de validação que controla o bypass por RBAC e registra auditoria obrigatória. | G21: 4 | H21: 4 TR: (1) Apontamentos – novo campo pos_fechamento e fluxo especial; (2) Periodos_Faturamento – validação de período fechado; (3) Profiles – autorização do gestor responsável; (4) Audit_Logs – registro obrigatório da operação retroativa. | I21: =IF(ISBLANK(C21),"",IF(L21="L","Baixa",IF(L21="A","Média",IF(L21="","","Alta")))) -> Alta | J21: =CONCATENATE(C21,L21) -> EEH | K21: =IF(ISBLANK(C21),"",IF(C21="ALI",IF(L21="L",7,IF(L21="A",10,15)),IF(C21="AIE",IF(L21="L",5,IF(L21="A",7,10)),IF(C21="SE",IF(L21="L",4,IF(L21="A",5,7)),IF(OR(C21="EE",C21="CE"),IF(L21="L",3,IF(L21="A",4,6)),0))))) -> 6 | L21: =IF(OR(ISBLANK(E21),ISBLANK(G21)),IF(OR(C21="ALI",C21="AIE"),"L",IF(OR(C21="EE",C21="SE",C21="CE"),"A","")),IF(C21="EE",IF(G21>=3,IF(E21>=5,"H","A"),IF(G21>=2,IF(E21>=16,"H",IF(E21<=4,"L","A")),IF(E21<=15,"L","A"))),IF(OR(C21="SE",C21="CE"),IF(G21>=4,IF(E21>=6,"H","A"),IF(G21>=2,IF(E21>=20,"H",IF(E21<=5,"L","A")),IF(E21<=19,"L","A"))),IF(OR(C21="ALI",C21="AIE"),IF(G21>=6,IF(E21>=20,"H","A"),IF(G21>=2,IF(E21>=51,"H",IF(E21<=19,"L","A")),IF(E21<=50,"L","A"))),"")))) -> H | M21: =CONCATENATE(C21,D21) -> EEI | N21: =IF(OR(K21="",K21=0),O21,K21) -> 6 | O21: =_xlfn.IFERROR(IF(NOT(ISERROR(VLOOKUP(C21,'Deflatores Sisp'!G$42:H$70,2,FALSE))),VLOOKUP(C21,'Deflatores Sisp'!G$42:H$70,2,FALSE),IF(OR(ISBLANK(D21),ISBLANK(C21)),"",VLOOKUP(D21,'Deflatores Sisp'!G$4:H$38,2,FALSE)*K21+VLOOKUP(D21,'Deflatores Sisp'!G$4:I$38,3,FALSE)))*W21,"") -> 5.7 | P21: x | Q21: x | R21: x | S21: x | U21: x | W21: =IF(V21="",SUM(Z21:AE21),IF(C21="PA",E21,100%)) -> 0.95 | Z21: =IF(P21="x",25%,0) -> 0.25 | AA21: =IF(Q21="x",10%,0) -> 0.1 | AB21: =IF(R21="x",40%,0) -> 0.4 | AC21: =IF(S21="x",15%,0) -> 0.15 | AD21: =IF(T21="x",5%,0) -> 0 | AE21: =IF(U21="x",5%,0) -> 0.05
... B26: Regra_Assinado_Vence_SEI_Selecao_Doc | C26: EE | D26: I | E26: 8 | F26: periodo_id, tipo_documento, documentos_candidatos[], documento_assinado_selecionado, documento_rascunho_descartado, motivo_selecao, data_assinatura_sei, protocolo_selecionado, flag_assinado_vence_aplicada. Implementação da regra 'Assinado Vence' na seleção de documentos SEI no modal de Assinaturas, garantindo que documentos assinados tenham prioridade sobre rascunhos/drafts para cálculos de faturamento e conformidade. | G26: 4 | H26: 4 TR: (1) SEI_Assinaturas – documentos assinados prioritários; (2) SEI_Exports – documentos exportados candidatos; (3) Documento_Periodo_Status – status de seleção vigente; (4) Periodos_Faturamento – contexto documental do período. | I26: =IF(ISBLANK(C26),"",IF(L26="L","Baixa",IF(L26="A","Média",IF(L26="","","Alta")))) -> Alta | J26: =CONCATENATE(C26,L26) -> EEH | K26: =IF(ISBLANK(C26),"",IF(C26="ALI",IF(L26="L",7,IF(L26="A",10,15)),IF(C26="AIE",IF(L26="L",5,IF(L26="A",7,10)),IF(C26="SE",IF(L26="L",4,IF(L26="A",5,7)),IF(OR(C26="EE",C26="CE"),IF(L26="L",3,IF(L26="A",4,6)),0))))) -> 6 | L26: =IF(OR(ISBLANK(E26),ISBLANK(G26)),IF(OR(C26="ALI",C26="AIE"),"L",IF(OR(C26="EE",C26="SE",C26="CE"),"A","")),IF(C26="EE",IF(G26>=3,IF(E26>=5,"H","A"),IF(G26>=2,IF(E26>=16,"H",IF(E26<=4,"L","A")),IF(E26<=15,"L","A"))),IF(OR(C26="SE",C26="CE"),IF(G26>=4,IF(E26>=6,"H","A"),IF(G26>=2,IF(E26>=20,"H",IF(E26<=5,"L","A")),IF(E26<=19,"L","A"))),IF(OR(C26="ALI",C26="AIE"),IF(G26>=6,IF(E26>=20,"H","A"),IF(G26>=2,IF(E26>=51,"H",IF(E26<=19,"L","A")),IF(E26<=50,"L","A"))),"")))) -> H | M26: =CONCATENATE(C26,D26) -> EEI | N26: =IF(OR(K26="",K26=0),O26,K26) -> 6 | O26: =_xlfn.IFERROR(IF(NOT(ISERROR(VLOOKUP(C26,'Deflatores Sisp'!G$42:H$70,2,FALSE))),VLOOKUP(C26,'Deflatores Sisp'!G$42:H$70,2,FALSE),IF(OR(ISBLANK(D26),ISBLANK(C26)),"",VLOOKUP(D26,'Deflatores Sisp'!G$4:H$38,2,FALSE)*K26+VLOOKUP(D26,'Deflatores Sisp'!G$4:I$38,3,FALSE)))*W26,"") -> 5.7 | P26: x | Q26: x | R26: x | S26: x | U26: x | W26: =IF(V26="",SUM(Z26:AE26),IF(C26="PA",E26,100%)) -> 0.95 | Z26: =IF(P26="x",25%,0) -> 0.25 | AA26: =IF(Q26="x",10%,0) -> 0.1 | AB26: =IF(R26="x",40%,0) -> 0.4 | AC26: =IF(S26="x",15%,0) -> 0.15 | AD26: =IF(T26="x",5%,0) -> 0 | AE26: =IF(U26="x",5%,0) -> 0.05
I27: =IF(ISBLANK(C27),"",IF(L27="L","Baixa",IF(L27="A","Média",IF(L27="","","Alta")))) | J27: =CONCATENATE(C27,L27) | K27: =IF(ISBLANK(C27),"",IF(C27="ALI",IF(L27="L",7,IF(L27="A",10,15)),IF(C27="AIE",IF(L27="L",5,IF(L27="A",7,10)),IF(C27="SE",IF(L27="L",4,IF(L27="A",5,7)),IF(OR(C27="EE",C27="CE"),IF(L27="L",3,IF(L27="A",4,6)),0))))) | L27: =IF(OR(ISBLANK(E27),ISBLANK(G27)),IF(OR(C27="ALI",C27="AIE"),"L",IF(OR(C27="EE",C27="SE",C27="CE"),"A","")),IF(C27="EE",IF(G27>=3,IF(E27>=5,"H","A"),IF(G27>=2,IF(E27>=16,"H",IF(E27<=4,"L","A")),IF(E27<=15,"L","A"))),IF(OR(C27="SE",C27="CE"),IF(G27>=4,IF(E27>=6,"H","A"),IF(G27>=2,IF(E27>=20,"H",IF(E27<=5,"L","A")),IF(E27<=19,"L","A"))),IF(OR(C27="ALI",C27="AIE"),IF(G27>=6,IF(E27>=20,"H","A"),IF(G27>=2,IF(E27>=51,"H",IF(E27<=19,"L","A")),IF(E27<=50,"L","A"))),"")))) | M27: =CONCATENATE(C27,D27) | N27: =IF(OR(K27="",K27=0),O27,K27) | O27: =_xlfn.IFERROR(IF(NOT(ISERROR(VLOOKUP(C27,'Deflatores Sisp'!G$42:H$70,2,FALSE))),VLOOKUP(C27,'Deflatores Sisp'!G$42:H$70,2,FALSE),IF(OR(ISBLANK(D27),ISBLANK(C27)),"",VLOOKUP(D27,'Deflatores Sisp'!G$4:H$38,2,FALSE)*K27+VLOOKUP(D27,'Deflatores Sisp'!G$4:I$38,3,FALSE)))*W27,"") | P27: x | Q27: x | R27: x | S27: x | U27: x | W27: =IF(V27="",SUM(Z27:AE27),IF(C27="PA",E27,100%)) -> 0.95 | Z27: =IF(P27="x",25%,0) -> 0.25 | AA27: =IF(Q27="x",10%,0) -> 0.1 | AB27: =IF(R27="x",40%,0) -> 0.4 | AC27: =IF(S27="x",15%,0) -> 0.15 | AD27: =IF(T27="x",5%,0) -> 0 | AE27: =IF(U27="x",5%,0) -> 0.05
I28: =IF(ISBLANK(C28),"",IF(L28="L","Baixa",IF(L28="A","Média",IF(L28="","","Alta")))) | J28: =CONCATENATE(C28,L28) | K28: =IF(ISBLANK(C28),"",IF(C28="ALI",IF(L28="L",7,IF(L28="A",10,15)),IF(C28="AIE",IF(L28="L",5,IF(L28="A",7,10)),IF(C28="SE",IF(L28="L",4,IF(L28="A",5,7)),IF(OR(C28="EE",C28="CE"),IF(L28="L",3,IF(L28="A",4,6)),0))))) | L28: =IF(OR(ISBLANK(E28),ISBLANK(G28)),IF(OR(C28="ALI",C28="AIE"),"L",IF(OR(C28="EE",C28="SE",C28="CE"),"A","")),IF(C28="EE",IF(G28>=3,IF(E28>=5,"H","A"),IF(G28>=2,IF(E28>=16,"H",IF(E28<=4,"L","A")),IF(E28<=15,"L","A"))),IF(OR(C28="SE",C28="CE"),IF(G28>=4,IF(E28>=6,"H","A"),IF(G28>=2,IF(E28>=20,"H",IF(E28<=5,"L","A")),IF(E28<=19,"L","A"))),IF(OR(C28="ALI",C28="AIE"),IF(G28>=6,IF(E28>=20,"H","A"),IF(G28>=2,IF(E28>=51,"H",IF(E28<=19,"L","A")),IF(E28<=50,"L","A"))),"")))) | M28: =CONCATENATE(C28,D28) | N28: =IF(OR(K28="",K28=0),O28,K28) | O28: =_xlfn.IFERROR(IF(NOT(ISERROR(VLOOKUP(C28,'Deflatores Sisp'!G$42:H$70,2,FALSE))),VLOOKUP(C28,'Deflatores Sisp'!G$42:H$70,2,FALSE),IF(OR(ISBLANK(D28),ISBLANK(C28)),"",VLOOKUP(D28,'Deflatores Sisp'!G$4:H$38,2,FALSE)*K28+VLOOKUP(D28,'Deflatores Sisp'!G$4:I$38,3,FALSE)))*W28,"") | P28: x | Q28: x | R28: x | S28: x | U28: x | W28: =IF(V28="",SUM(Z28:AE28),IF(C28="PA",E28,100%)) -> 0.95 | Z28: =IF(P28="x",25%,0) -> 0.25 | AA28: =IF(Q28="x",10%,0) -> 0.1 | AB28: =IF(R28="x",40%,0) -> 0.4 | AC28: =IF(S28="x",15%,0) -> 0.15 | AD28: =IF(T28="x",5%,0) -> 0 | AE28: =IF(U28="x",5%,0) -> 0.05
I29: =IF(ISBLANK(C29),"",IF(L29="L","Baixa",IF(L29="A","Média",IF(L29="","","Alta")))) | J29: =CONCATENATE(C29,L29) | K29: =IF(ISBLANK(C29),"",IF(C29="ALI",IF(L29="L",7,IF(L29="A",10,15)),IF(C29="AIE",IF(L29="L",5,IF(L29="A",7,10)),IF(C29="SE",IF(L29="L",4,IF(L29="A",5,7)),IF(OR(C29="EE",C29="CE"),IF(L29="L",3,IF(L29="A",4,6)),0))))) | L29: =IF(OR(ISBLANK(E29),ISBLANK(G29)),IF(OR(C29="ALI",C29="AIE"),"L",IF(OR(C29="EE",C29="SE",C29="CE"),"A","")),IF(C29="EE",IF(G29>=3,IF(E29>=5,"H","A"),IF(G29>=2,IF(E29>=16,"H",IF(E29<=4,"L","A")),IF(E29<=15,"L","A"))),IF(OR(C29="SE",C29="CE"),IF(G29>=4,IF(E29>=6,"H","A"),IF(G29>=2,IF(E29>=20,"H",IF(E29<=5,"L","A")),IF(E29<=19,"L","A"))),IF(OR(C29="ALI",C29="AIE"),IF(G29>=6,IF(E29>=20,"H","A"),IF(G29>=2,IF(E29>=51,"H",IF(E29<=19,"L","A")),IF(E29<=50,"L","A"))),"")))) | M29: =CONCATENATE(C29,D29) | N29: =IF(OR(K29="",K29=0),O29,K29) | O29: =_xlfn.IFERROR(IF(NOT(ISERROR(VLOOKUP(C29,'Deflatores Sisp'!G$42:H$70,2,FALSE))),VLOOKUP(C29,'Deflatores Sisp'!G$42:H$70,2,FALSE),IF(OR(ISBLANK(D29),ISBLANK(C29)),"",VLOOKUP(D29,'Deflatores Sisp'!G$4:H$38,2,FALSE)*K29+VLOOKUP(D29,'Deflatores Sisp'!G$4:I$38,3,FALSE)))*W29,"") | P29: x | Q29: x | R29: x | S29: x | U29: x | W29: =IF(V29="",SUM(Z29:AE29),IF(C29="PA",E29,100%)) -> 0.95 | Z29: =IF(P29="x",25%,0) -> 0.25 | AA29: =IF(Q29="x",10%,0) -> 0.1 | AB29: =IF(R29="x",40%,0) -> 0.4 | AC29: =IF(S29="x",15%,0) -> 0.15 | AD29: =IF(T29="x",5%,0) -> 0 | AE29: =IF(U29="x",5%,0) -> 0.05
I30: =IF(ISBLANK(C30),"",IF(L30="L","Baixa",IF(L30="A","Média",IF(L30="","","Alta")))) | J30: =CONCATENATE(C30,L30) | K30: =IF(ISBLANK(C30),"",IF(C30="ALI",IF(L30="L",7,IF(L30="A",10,15)),IF(C30="AIE",IF(L30="L",5,IF(L30="A",7,10)),IF(C30="SE",IF(L30="L",4,IF(L30="A",5,7)),IF(OR(C30="EE",C30="CE"),IF(L30="L",3,IF(L30="A",4,6)),0))))) | L30: =IF(OR(ISBLANK(E30),ISBLANK(G30)),IF(OR(C30="ALI",C30="AIE"),"L",IF(OR(C30="EE",C30="SE",C30="CE"),"A","")),IF(C30="EE",IF(G30>=3,IF(E30>=5,"H","A"),IF(G30>=2,IF(E30>=16,"H",IF(E30<=4,"L","A")),IF(E30<=15,"L","A"))),IF(OR(C30="SE",C30="CE"),IF(G30>=4,IF(E30>=6,"H","A"),IF(G30>=2,IF(E30>=20,"H",IF(E30<=5,"L","A")),IF(E30<=19,"L","A"))),IF(OR(C30="ALI",C30="AIE"),IF(G30>=6,IF(E30>=20,"H","A"),IF(G30>=2,IF(E30>=51,"H",IF(E30<=19,"L","A")),IF(E30<=50,"L","A"))),"")))) | M30: =CONCATENATE(C30,D30) | N30: =IF(OR(K30="",K30=0),O30,K30) | O30: =_xlfn.IFERROR(IF(NOT(ISERROR(VLOOKUP(C30,'Deflatores Sisp'!G$42:H$70,2,FALSE))),VLOOKUP(C30,'Deflatores Sisp'!G$42:H$70,2,FALSE),IF(OR(ISBLANK(D30),ISBLANK(C30)),"",VLOOKUP(D30,'Deflatores Sisp'!G$4:H$38,2,FALSE)*K30+VLOOKUP(D30,'Deflatores Sisp'!G$4:I$38,3,FALSE)))*W30,"") | P30: x | Q30: x | R30: x | S30: x | U30: x | W30: =IF(V30="",SUM(Z30:AE30),IF(C30="PA",E30,100%)) -> 0.95 | Z30: =IF(P30="x",25%,0) -> 0.25 | AA30: =IF(Q30="x",10%,0) -> 0.1 | AB30: =IF(R30="x",40%,0) -> 0.4 | AC30: =IF(S30="x",15%,0) -> 0.15 | AD30: =IF(T30="x",5%,0) -> 0 | AE30: =IF(U30="x",5%,0) -> 0.05
I31: =IF(ISBLANK(C31),"",IF(L31="L","Baixa",IF(L31="A","Média",IF(L31="","","Alta")))) | J31: =CONCATENATE(C31,L31) | K31: =IF(ISBLANK(C31),"",IF(C31="ALI",IF(L31="L",7,IF(L31="A",10,15)),IF(C31="AIE",IF(L31="L",5,IF(L31="A",7,10)),IF(C31="SE",IF(L31="L",4,IF(L31="A",5,7)),IF(OR(C31="EE",C31="CE"),IF(L31="L",3,IF(L31="A",4,6)),0))))) | L31: =IF(OR(ISBLANK(E31),ISBLANK(G31)),IF(OR(C31="ALI",C31="AIE"),"L",IF(OR(C31="EE",C31="SE",C31="CE"),"A","")),IF(C31="EE",IF(G31>=3,IF(E31>=5,"H","A"),IF(G31>=2,IF(E31>=16,"H",IF(E31<=4,"L","A")),IF(E31<=15,"L","A"))),IF(OR(C31="SE",C31="CE"),IF(G31>=4,IF(E31>=6,"H","A"),IF(G31>=2,IF(E31>=20,"H",IF(E31<=5,"L","A")),IF(E31<=19,"L","A"))),IF(OR(C31="ALI",C31="AIE"),IF(G31>=6,IF(E31>=20,"H","A"),IF(G31>=2,IF(E31>=51,"H",IF(E31<=19,"L","A")),IF(E31<=50,"L","A"))),"")))) | M31: =CONCATENATE(C31,D31) | N31: =IF(OR(K31="",K31=0),O31,K31) | O31: =_xlfn.IFERROR(IF(NOT(ISERROR(VLOOKUP(C31,'Deflatores Sisp'!G$42:H$70,2,FALSE))),VLOOKUP(C31,'Deflatores Sisp'!G$42:H$70,2,FALSE),IF(OR(ISBLANK(D31),ISBLANK(C31)),"",VLOOKUP(D31,'Deflatores Sisp'!G$4:H$38,2,FALSE)*K31+VLOOKUP(D31,'Deflatores Sisp'!G$4:I$38,3,FALSE)))*W31,"") | P31: x | Q31: x | R31: x | S31: x | U31: x | W31: =IF(V31="",SUM(Z31:AE31),IF(C31="PA",E31,100%)) -> 0.95 | Z31: =IF(P31="x",25%,0) -> 0.25 | AA31: =IF(Q31="x",10%,0) -> 0.1 | AB31: =IF(R31="x",40%,0) -> 0.4 | AC31: =IF(S31="x",15%,0) -> 0.15 | AD31: =IF(T31="x",5%,0) -> 0 | AE31: =IF(U31="x",5%,0) -> 0.05
I32: =IF(ISBLANK(C32),"",IF(L32="L","Baixa",IF(L32="A","Média",IF(L32="","","Alta")))) | J32: =CONCATENATE(C32,L32) | K32: =IF(ISBLANK(C32),"",IF(C32="ALI",IF(L32="L",7,IF(L32="A",10,15)),IF(C32="AIE",IF(L32="L",5,IF(L32="A",7,10)),IF(C32="SE",IF(L32="L",4,IF(L32="A",5,7)),IF(OR(C32="EE",C32="CE"),IF(L32="L",3,IF(L32="A",4,6)),0))))) | L32: =IF(OR(ISBLANK(E32),ISBLANK(G32)),IF(OR(C32="ALI",C32="AIE"),"L",IF(OR(C32="EE",C32="SE",C32="CE"),"A","")),IF(C32="EE",IF(G32>=3,IF(E32>=5,"H","A"),IF(G32>=2,IF(E32>=16,"H",IF(E32<=4,"L","A")),IF(E32<=15,"L","A"))),IF(OR(C32="SE",C32="CE"),IF(G32>=4,IF(E32>=6,"H","A"),IF(G32>=2,IF(E32>=20,"H",IF(E32<=5,"L","A")),IF(E32<=19,"L","A"))),IF(OR(C32="ALI",C32="AIE"),IF(G32>=6,IF(E32>=20,"H","A"),IF(G32>=2,IF(E32>=51,"H",IF(E32<=19,"L","A")),IF(E32<=50,"L","A"))),"")))) | M32: =CONCATENATE(C32,D32) | N32: =IF(OR(K32="",K32=0),O32,K32) | O32: =_xlfn.IFERROR(IF(NOT(ISERROR(VLOOKUP(C32,'Deflatores Sisp'!G$42:H$70,2,FALSE))),VLOOKUP(C32,'Deflatores Sisp'!G$42:H$70,2,FALSE),IF(OR(ISBLANK(D32),ISBLANK(C32)),"",VLOOKUP(D32,'Deflatores Sisp'!G$4:H$38,2,FALSE)*K32+VLOOKUP(D32,'Deflatores Sisp'!G$4:I$38,3,FALSE)))*W32,"") | P32: x | Q32: x | R32: x | S32: x | U32: x | W32: =IF(V32="",SUM(Z32:AE32),IF(C32="PA",E32,100%)) -> 0.95 | Z32: =IF(P32="x",25%,0) -> 0.25 | AA32: =IF(Q32="x",10%,0) -> 0.1 | AB32: =IF(R32="x",40%,0) -> 0.4 | AC32: =IF(S32="x",15%,0) -> 0.15 | AD32: =IF(T32="x",5%,0) -> 0 | AE32: =IF(U32="x",5%,0) -> 0.05
I33: =IF(ISBLANK(C33),"",IF(L33="L","Baixa",IF(L33="A","Média",IF(L33="","","Alta")))) | J33: =CONCATENATE(C33,L33) | K33: =IF(ISBLANK(C33),"",IF(C33="ALI",IF(L33="L",7,IF(L33="A",10,15)),IF(C33="AIE",IF(L33="L",5,IF(L33="A",7,10)),IF(C33="SE",IF(L33="L",4,IF(L33="A",5,7)),IF(OR(C33="EE",C33="CE"),IF(L33="L",3,IF(L33="A",4,6)),0))))) | L33: =IF(OR(ISBLANK(E33),ISBLANK(G33)),IF(OR(C33="ALI",C33="AIE"),"L",IF(OR(C33="EE",C33="SE",C33="CE"),"A","")),IF(C33="EE",IF(G33>=3,IF(E33>=5,"H","A"),IF(G33>=2,IF(E33>=16,"H",IF(E33<=4,"L","A")),IF(E33<=15,"L","A"))),IF(OR(C33="SE",C33="CE"),IF(G33>=4,IF(E33>=6,"H","A"),IF(G33>=2,IF(E33>=20,"H",IF(E33<=5,"L","A")),IF(E33<=19,"L","A"))),IF(OR(C33="ALI",C33="AIE"),IF(G33>=6,IF(E33>=20,"H","A"),IF(G33>=2,IF(E33>=51,"H",IF(E33<=19,"L","A")),IF(E33<=50,"L","A"))),"")))) | M33: =CONCATENATE(C33,D33) | N33: =IF(OR(K33="",K33=0),O33,K33) | O33: =_xlfn.IFERROR(IF(NOT(ISERROR(VLOOKUP(C33,'Deflatores Sisp'!G$42:H$70,2,FALSE))),VLOOKUP(C33,'Deflatores Sisp'!G$42:H$70,2,FALSE),IF(OR(ISBLANK(D33),ISBLANK(C33)),"",VLOOKUP(D33,'Deflatores Sisp'!G$4:H$38,2,FALSE)*K33+VLOOKUP(D33,'Deflatores Sisp'!G$4:I$38,3,FALSE)))*W33,"") | P33: x | Q33: x | R33: x | S33: x | U33: x | W33: =IF(V33="",SUM(Z33:AE33),IF(C33="PA",E33,100%)) -> 0.95 | Z33: =IF(P33="x",25%,0) -> 0.25 | AA33: =IF(Q33="x",10%,0) -> 0.1 | AB33: =IF(R33="x",40%,0) -> 0.4 | AC33: =IF(S33="x",15%,0) -> 0.15 | AD33: =IF(T33="x",5%,0) -> 0 | AE33: =IF(U33="x",5%,0) -> 0.05
I34: =IF(ISBLANK(C34),"",IF(L34="L","Baixa",IF(L34="A","Média",IF(L34="","","Alta")))) | J34: =CONCATENATE(C34,L34) | K34: =IF(ISBLANK(C34),"",IF(C34="ALI",IF(L34="L",7,IF(L34="A",10,15)),IF(C34="AIE",IF(L34="L",5,IF(L34="A",7,10)),IF(C34="SE",IF(L34="L",4,IF(L34="A",5,7)),IF(OR(C34="EE",C34="CE"),IF(L34="L",3,IF(L34="A",4,6)),0))))) | L34: =IF(OR(ISBLANK(E34),ISBLANK(G34)),IF(OR(C34="ALI",C34="AIE"),"L",IF(OR(C34="EE",C34="SE",C34="CE"),"A","")),IF(C34="EE",IF(G34>=3,IF(E34>=5,"H","A"),IF(G34>=2,IF(E34>=16,"H",IF(E34<=4,"L","A")),IF(E34<=15,"L","A"))),IF(OR(C34="SE",C34="CE"),IF(G34>=4,IF(E34>=6,"H","A"),IF(G34>=2,IF(E34>=20,"H",IF(E34<=5,"L","A")),IF(E34<=19,"L","A"))),IF(OR(C34="ALI",C34="AIE"),IF(G34>=6,IF(E34>=20,"H","A"),IF(G34>=2,IF(E34>=51,"H",IF(E34<=19,"L","A")),IF(E34<=50,"L","A"))),"")))) | M34: =CONCATENATE(C34,D34) | N34: =IF(OR(K34="",K34=0),O34,K34) | O34: =_xlfn.IFERROR(IF(NOT(ISERROR(VLOOKUP(C34,'Deflatores Sisp'!G$42:H$70,2,FALSE))),VLOOKUP(C34,'Deflatores Sisp'!G$42:H$70,2,FALSE),IF(OR(ISBLANK(D34),ISBLANK(C34)),"",VLOOKUP(D34,'Deflatores Sisp'!G$4:H$38,2,FALSE)*K34+VLOOKUP(D34,'Deflatores Sisp'!G$4:I$38,3,FALSE)))*W34,"") | P34: x | Q34: x | R34: x | S34: x | U34: x | W34: =IF(V34="",SUM(Z34:AE34),IF(C34="PA",E34,100%)) -> 0.95 | Z34: =IF(P34="x",25%,0) -> 0.25 | AA34: =IF(Q34="x",10%,0) -> 0.1 | AB34: =IF(R34="x",40%,0) -> 0.4 | AC34: =IF(S34="x",15%,0) -> 0.15 | AD34: =IF(T34="x",5%,0) -> 0 | AE34: =IF(U34="x",5%,0) -> 0.05
I35: =IF(ISBLANK(C35),"",IF(L35="L","Baixa",IF(L35="A","Média",IF(L35="","","Alta")))) | J35: =CONCATENATE(C35,L35) | K35: =IF(ISBLANK(C35),"",IF(C35="ALI",IF(L35="L",7,IF(L35="A",10,15)),IF(C35="AIE",IF(L35="L",5,IF(L35="A",7,10)),IF(C35="SE",IF(L35="L",4,IF(L35="A",5,7)),IF(OR(C35="EE",C35="CE"),IF(L35="L",3,IF(L35="A",4,6)),0))))) | L35: =IF(OR(ISBLANK(E35),ISBLANK(G35)),IF(OR(C35="ALI",C35="AIE"),"L",IF(OR(C35="EE",C35="SE",C35="CE"),"A","")),IF(C35="EE",IF(G35>=3,IF(E35>=5,"H","A"),IF(G35>=2,IF(E35>=16,"H",IF(E35<=4,"L","A")),IF(E35<=15,"L","A"))),IF(OR(C35="SE",C35="CE"),IF(G35>=4,IF(E35>=6,"H","A"),IF(G35>=2,IF(E35>=20,"H",IF(E35<=5,"L","A")),IF(E35<=19,"L","A"))),IF(OR(C35="ALI",C35="AIE"),IF(G35>=6,IF(E35>=20,"H","A"),IF(G35>=2,IF(E35>=51,"H",IF(E35<=19,"L","A")),IF(E35<=50,"L","A"))),"")))) | M35: =CONCATENATE(C35,D35) | N35: =IF(OR(K35="",K35=0),O35,K35) | O35: =_xlfn.IFERROR(IF(NOT(ISERROR(VLOOKUP(C35,'Deflatores Sisp'!G$42:H$70,2,FALSE))),VLOOKUP(C35,'Deflatores Sisp'!G$42:H$70,2,FALSE),IF(OR(ISBLANK(D35),ISBLANK(C35)),"",VLOOKUP(D35,'Deflatores Sisp'!G$4:H$38,2,FALSE)*K35+VLOOKUP(D35,'Deflatores Sisp'!G$4:I$38,3,FALSE)))*W35,"") | P35: x | Q35: x | R35: x | S35: x | U35: x | W35: =IF(V35="",SUM(Z35:AE35),IF(C35="PA",E35,100%)) -> 0.95 | Z35: =IF(P35="x",25%,0) -> 0.25 | AA35: =IF(Q35="x",10%,0) -> 0.1 | AB35: =IF(R35="x",40%,0) -> 0.4 | AC35: =IF(S35="x",15%,0) -> 0.15 | AD35: =IF(T35="x",5%,0) -> 0 | AE35: =IF(U35="x",5%,0) -> 0.05
I36: =IF(ISBLANK(C36),"",IF(L36="L","Baixa",IF(L36="A","Média",IF(L36="","","Alta")))) | J36: =CONCATENATE(C36,L36) | K36: =IF(ISBLANK(C36),"",IF(C36="ALI",IF(L36="L",7,IF(L36="A",10,15)),IF(C36="AIE",IF(L36="L",5,IF(L36="A",7,10)),IF(C36="SE",IF(L36="L",4,IF(L36="A",5,7)),IF(OR(C36="EE",C36="CE"),IF(L36="L",3,IF(L36="A",4,6)),0))))) | L36: =IF(OR(ISBLANK(E36),ISBLANK(G36)),IF(OR(C36="ALI",C36="AIE"),"L",IF(OR(C36="EE",C36="SE",C36="CE"),"A","")),IF(C36="EE",IF(G36>=3,IF(E36>=5,"H","A"),IF(G36>=2,IF(E36>=16,"H",IF(E36<=4,"L","A")),IF(E36<=15,"L","A"))),IF(OR(C36="SE",C36="CE"),IF(G36>=4,IF(E36>=6,"H","A"),IF(G36>=2,IF(E36>=20,"H",IF(E36<=5,"L","A")),IF(E36<=19,"L","A"))),IF(OR(C36="ALI",C36="AIE"),IF(G36>=6,IF(E36>=20,"H","A"),IF(G36>=2,IF(E36>=51,"H",IF(E36<=19,"L","A")),IF(E36<=50,"L","A"))),"")))) | M36: =CONCATENATE(C36,D36) | N36: =IF(OR(K36="",K36=0),O36,K36) | O36: =_xlfn.IFERROR(IF(NOT(ISERROR(VLOOKUP(C36,'Deflatores Sisp'!G$42:H$70,2,FALSE))),VLOOKUP(C36,'Deflatores Sisp'!G$42:H$70,2,FALSE),IF(OR(ISBLANK(D36),ISBLANK(C36)),"",VLOOKUP(D36,'Deflatores Sisp'!G$4:H$38,2,FALSE)*K36+VLOOKUP(D36,'Deflatores Sisp'!G$4:I$38,3,FALSE)))*W36,"") | P36: x | Q36: x | R36: x | S36: x | U36: x | W36: =IF(V36="",SUM(Z36:AE36),IF(C36="PA",E36,100%)) -> 0.95 | Z36: =IF(P36="x",25%,0) -> 0.25 | AA36: =IF(Q36="x",10%,0) -> 0.1 | AB36: =IF(R36="x",40%,0) -> 0.4 | AC36: =IF(S36="x",15%,0) -> 0.15 | AD36: =IF(T36="x",5%,0) -> 0 | AE36: =IF(U36="x",5%,0) -> 0.05
I37: =IF(ISBLANK(C37),"",IF(L37="L","Baixa",IF(L37="A","Média",IF(L37="","","Alta")))) | J37: =CONCATENATE(C37,L37) | K37: =IF(ISBLANK(C37),"",IF(C37="ALI",IF(L37="L",7,IF(L37="A",10,15)),IF(C37="AIE",IF(L37="L",5,IF(L37="A",7,10)),IF(C37="SE",IF(L37="L",4,IF(L37="A",5,7)),IF(OR(C37="EE",C37="CE"),IF(L37="L",3,IF(L37="A",4,6)),0))))) | L37: =IF(OR(ISBLANK(E37),ISBLANK(G37)),IF(OR(C37="ALI",C37="AIE"),"L",IF(OR(C37="EE",C37="SE",C37="CE"),"A","")),IF(C37="EE",IF(G37>=3,IF(E37>=5,"H","A"),IF(G37>=2,IF(E37>=16,"H",IF(E37<=4,"L","A")),IF(E37<=15,"L","A"))),IF(OR(C37="SE",C37="CE"),IF(G37>=4,IF(E37>=6,"H","A"),IF(G37>=2,IF(E37>=20,"H",IF(E37<=5,"L","A")),IF(E37<=19,"L","A"))),IF(OR(C37="ALI",C37="AIE"),IF(G37>=6,IF(E37>=20,"H","A"),IF(G37>=2,IF(E37>=51,"H",IF(E37<=19,"L","A")),IF(E37<=50,"L","A"))),"")))) | M37: =CONCATENATE(C37,D37) | N37: =IF(OR(K37="",K37=0),O37,K37) | O37: =_xlfn.IFERROR(IF(NOT(ISERROR(VLOOKUP(C37,'Deflatores Sisp'!G$42:H$70,2,FALSE))),VLOOKUP(C37,'Deflatores Sisp'!G$42:H$70,2,FALSE),IF(OR(ISBLANK(D37),ISBLANK(C37)),"",VLOOKUP(D37,'Deflatores Sisp'!G$4:H$38,2,FALSE)*K37+VLOOKUP(D37,'Deflatores Sisp'!G$4:I$38,3,FALSE)))*W37,"") | P37: x | Q37: x | R37: x | S37: x | U37: x | W37: =IF(V37="",SUM(Z37:AE37),IF(C37="PA",E37,100%)) -> 0.95 | Z37: =IF(P37="x",25%,0) -> 0.25 | AA37: =IF(Q37="x",10%,0) -> 0.1 | AB37: =IF(R37="x",40%,0) -> 0.4 | AC37: =IF(S37="x",15%,0) -> 0.15 | AD37: =IF(T37="x",5%,0) -> 0 | AE37: =IF(U37="x",5%,0) -> 0.05
I38: =IF(ISBLANK(C38),"",IF(L38="L","Baixa",IF(L38="A","Média",IF(L38="","","Alta")))) | J38: =CONCATENATE(C38,L38) | K38: =IF(ISBLANK(C38),"",IF(C38="ALI",IF(L38="L",7,IF(L38="A",10,15)),IF(C38="AIE",IF(L38="L",5,IF(L38="A",7,10)),IF(C38="SE",IF(L38="L",4,IF(L38="A",5,7)),IF(OR(C38="EE",C38="CE"),IF(L38="L",3,IF(L38="A",4,6)),0))))) | L38: =IF(OR(ISBLANK(E38),ISBLANK(G38)),IF(OR(C38="ALI",C38="AIE"),"L",IF(OR(C38="EE",C38="SE",C38="CE"),"A","")),IF(C38="EE",IF(G38>=3,IF(E38>=5,"H","A"),IF(G38>=2,IF(E38>=16,"H",IF(E38<=4,"L","A")),IF(E38<=15,"L","A"))),IF(OR(C38="SE",C38="CE"),IF(G38>=4,IF(E38>=6,"H","A"),IF(G38>=2,IF(E38>=20,"H",IF(E38<=5,"L","A")),IF(E38<=19,"L","A"))),IF(OR(C38="ALI",C38="AIE"),IF(G38>=6,IF(E38>=20,"H","A"),IF(G38>=2,IF(E38>=51,"H",IF(E38<=19,"L","A")),IF(E38<=50,"L","A"))),"")))) | M38: =CONCATENATE(C38,D38) | N38: =IF(OR(K38="",K38=0),O38,K38) | O38: =_xlfn.IFERROR(IF(NOT(ISERROR(VLOOKUP(C38,'Deflatores Sisp'!G$42:H$70,2,FALSE))),VLOOKUP(C38,'Deflatores Sisp'!G$42:H$70,2,FALSE),IF(OR(ISBLANK(D38),ISBLANK(C38)),"",VLOOKUP(D38,'Deflatores Sisp'!G$4:H$38,2,FALSE)*K38+VLOOKUP(D38,'Deflatores Sisp'!G$4:I$38,3,FALSE)))*W38,"") | P38: x | Q38: x | R38: x | S38: x | U38: x | W38: =IF(V38="",SUM(Z38:AE38),IF(C38="PA",E38,100%)) -> 0.95 | Z38: =IF(P38="x",25%,0) -> 0.25 | AA38: =IF(Q38="x",10%,0) -> 0.1 | AB38: =IF(R38="x",40%,0) -> 0.4 | AC38: =IF(S38="x",15%,0) -> 0.15 | AD38: =IF(T38="x",5%,0) -> 0 | AE38: =IF(U38="x",5%,0) -> 0.05
... I149: =IF(ISBLANK(C149),"",IF(L149="L","Baixa",IF(L149="A","Média",IF(L149="","","Alta")))) | J149: =CONCATENATE(C149,L149) | K149: =IF(ISBLANK(C149),"",IF(C149="ALI",IF(L149="L",7,IF(L149="A",10,15)),IF(C149="AIE",IF(L149="L",5,IF(L149="A",7,10)),IF(C149="SE",IF(L149="L",4,IF(L149="A",5,7)),IF(OR(C149="EE",C149="CE"),IF(L149="L",3,IF(L149="A",4,6)),0))))) | L149: =IF(OR(ISBLANK(E149),ISBLANK(G149)),IF(OR(C149="ALI",C149="AIE"),"L",IF(OR(C149="EE",C149="SE",C149="CE"),"A","")),IF(C149="EE",IF(G149>=3,IF(E149>=5,"H","A"),IF(G149>=2,IF(E149>=16,"H",IF(E149<=4,"L","A")),IF(E149<=15,"L","A"))),IF(OR(C149="SE",C149="CE"),IF(G149>=4,IF(E149>=6,"H","A"),IF(G149>=2,IF(E149>=20,"H",IF(E149<=5,"L","A")),IF(E149<=19,"L","A"))),IF(OR(C149="ALI",C149="AIE"),IF(G149>=6,IF(E149>=20,"H","A"),IF(G149>=2,IF(E149>=51,"H",IF(E149<=19,"L","A")),IF(E149<=50,"L","A"))),"")))) | M149: =CONCATENATE(C149,D149) | N149: =IF(OR(K149="",K149=0),O149,K149) | O149: =_xlfn.IFERROR(IF(NOT(ISERROR(VLOOKUP(C149,'Deflatores Sisp'!G$42:H$70,2,FALSE))),VLOOKUP(C149,'Deflatores Sisp'!G$42:H$70,2,FALSE),IF(OR(ISBLANK(D149),ISBLANK(C149)),"",VLOOKUP(D149,'Deflatores Sisp'!G$4:H$38,2,FALSE)*K149+VLOOKUP(D149,'Deflatores Sisp'!G$4:I$38,3,FALSE)))*W149,"") | P149: x | Q149: x | R149: x | S149: x | U149: x | W149: =IF(V149="",SUM(Z149:AE149),IF(C149="PA",E149,100%)) -> 0.95 | Z149: =IF(P149="x",25%,0) -> 0.25 | AA149: =IF(Q149="x",10%,0) -> 0.1 | AB149: =IF(R149="x",40%,0) -> 0.4 | AC149: =IF(S149="x",15%,0) -> 0.15 | AD149: =IF(T149="x",5%,0) -> 0 | AE149: =IF(U149="x",5%,0) -> 0.05
I166: =IF(ISBLANK(C166),"",IF(L166="L","Baixa",IF(L166="A","Média",IF(L166="","","Alta")))) | J166: =CONCATENATE(C166,L166) | K166: =IF(ISBLANK(C166),"",IF(C166="ALI",IF(L166="L",7,IF(L166="A",10,15)),IF(C166="AIE",IF(L166="L",5,IF(L166="A",7,10)),IF(C166="SE",IF(L166="L",4,IF(L166="A",5,7)),IF(OR(C166="EE",C166="CE"),IF(L166="L",3,IF(L166="A",4,6)),0))))) | L166: =IF(OR(ISBLANK(E166),ISBLANK(G166)),IF(OR(C166="ALI",C166="AIE"),"L",IF(OR(C166="EE",C166="SE",C166="CE"),"A","")),IF(C166="EE",IF(G166>=3,IF(E166>=5,"H","A"),IF(G166>=2,IF(E166>=16,"H",IF(E166<=4,"L","A")),IF(E166<=15,"L","A"))),IF(OR(C166="SE",C166="CE"),IF(G166>=4,IF(E166>=6,"H","A"),IF(G166>=2,IF(E166>=20,"H",IF(E166<=5,"L","A")),IF(E166<=19,"L","A"))),IF(OR(C166="ALI",C166="AIE"),IF(G166>=6,IF(E166>=20,"H","A"),IF(G166>=2,IF(E166>=51,"H",IF(E166<=19,"L","A")),IF(E166<=50,"L","A"))),"")))) | M166: =CONCATENATE(C166,D166) | N166: =IF(OR(K166="",K166=0),O166,K166) | O166: =_xlfn.IFERROR(IF(NOT(ISERROR(VLOOKUP(C166,'Deflatores Sisp'!G$42:H$70,2,FALSE))),VLOOKUP(C166,'Deflatores Sisp'!G$42:H$70,2,FALSE),IF(OR(ISBLANK(D166),ISBLANK(C166)),"",VLOOKUP(D166,'Deflatores Sisp'!G$4:H$38,2,FALSE)*K166+VLOOKUP(D166,'Deflatores Sisp'!G$4:I$38,3,FALSE)))*W166,"") | Z166: =IF(P166="x",25%,0) -> 0 | AA166: =IF(Q166="x",10%,0) -> 0 | AB166: =IF(R166="x",40%,0) -> 0 | AC166: =IF(S166="x",15%,0) -> 0 | AD166: =IF(T166="x",5%,0) -> 0 | AE166: =IF(U166="x",5%,0) -> 0

Sheet Deflatores Sisp
A1: Itens Não Mensuráveis
A2: Tipo de Manutenção na Função | G2: Sigla | H2: Contribuição em PF Local | J2: PF IFPUG | K2: PF Local FS | L2: Fator Disciplina | M2: Tamanho Ajustado | N2: =SUM(L4:L38) -> 99.75
A3: Contrato | B3: Descrição | F3: Origem | H3: Percentual (%) | I3: Fixa (PF)
A4: SISP 2.3 | B4: Inclusão | G4: I | H4: 1 | J4: =SUMIF('Funções'!$D$8:$D$110,G4,'Funções'!$K$8:$K$110) -> 105 | K4: =IF(H4="",COUNTIF('Funções'!D$8:D$110,G4)*I4,H4*J4) -> 105 | L4: =SUMIF('Funções'!$D$8:$D$110,G4,'Funções'!$O$8:$O$110) -> 99.75 | M4: EvolutivaI
A5: SISP 2.3 | B5: Alteração (sem conhecimento do Fator de Impacto) | F5: SISP – 4.2 Projeto de Melhoria | G5: A | H5: 0.8 | J5: =SUMIF('Funções'!$D$8:$D$110,G5,'Funções'!$K$8:$K$110) -> 0 | K5: =IF(H5="",COUNTIF('Funções'!D$8:D$110,G5)*I5,H5*J5) -> 0 | L5: =SUMIF('Funções'!$D$8:$D$110,G5,'Funções'!$O$8:$O$110) -> 0 | M5: EvolutivaA
A6: SISP 2.3 | B6: Exclusão | F6: SISP – 4.2 Projeto de Melhoria | G6: E | H6: 0.4 | J6: =SUMIF('Funções'!$D$8:$D$110,G6,'Funções'!$K$8:$K$110) -> 0 | K6: =IF(H6="",COUNTIF('Funções'!D$8:D$110,G6)*I6,H6*J6) -> 0 | L6: =SUMIF('Funções'!$D$8:$D$110,G6,'Funções'!$O$8:$O$110) -> 0 | M6: EvolutivaE
A7: SISP 2.3 | B7: Alteração (50%) de função desenvolvida ou já alterada pela empresa atual | F7: SISP – 4.2 Projeto de Melhoria | G7: A50 | H7: 0.5 | J7: =SUMIF('Funções'!$D$8:$D$110,G7,'Funções'!$K$8:$K$110) -> 0 | K7: =IF(H7="",COUNTIF('Funções'!D$8:D$110,G7)*I7,H7*J7) -> 0 | L7: =SUMIF('Funções'!$D$8:$D$110,G7,'Funções'!$O$8:$O$110) -> 0 | M7: EvolutivaA
A8: SISP 2.3 | B8: FI = 75% para funcionalidade de sistema não desenvolvida ou mantida por meio de um projeto de melhoria pela empresa contratada e sem necessidade de redocumentação da funcionalidade. | F8: SISP – 4.2 Projeto de Melhoria | G8: A75 | H8: 0.75 | J8: =SUMIF('Funções'!$D$8:$D$110,G8,'Funções'!$K$8:$K$110) -> 0 | K8: =IF(H8="",COUNTIF('Funções'!D$8:D$110,G8)*I8,H8*J8) -> 0 | L8: =SUMIF('Funções'!$D$8:$D$110,G8,'Funções'!$O$8:$O$110) -> 0 | M8: EvolutivaA
A9: SISP 2.3 | B9: Alteração (75%+15%): o mesmo acima + redocumentar a função | F9: SISP – 4.2 Projeto de Melhoria | G9: A90 | H9: 0.9 | J9: =SUMIF('Funções'!$D$8:$D$110,G9,'Funções'!$K$8:$K$110) -> 0 | K9: =IF(H9="",COUNTIF('Funções'!D$8:D$110,G9)*I9,H9*J9) -> 0 | L9: =SUMIF('Funções'!$D$8:$D$110,G9,'Funções'!$O$8:$O$110) -> 0 | M9: EvolutivaA
A10: SISP 2.3 | B10: Migração de Dados | F10: SISP – 4.3 Projetos de Migração de Dados | G10: PMD | H10: 1 | J10: =SUMIF('Funções'!$D$8:$D$110,G10,'Funções'!$K$8:$K$110) -> 0 | K10: =IF(H10="",COUNTIF('Funções'!D$8:D$110,G10)*I10,H10*J10) -> 0 | L10: =SUMIF('Funções'!$D$8:$D$110,G10,'Funções'!$O$8:$O$110) -> 0 | M10: EvolutivaI
A11: SISP 2.3 | B11: Corretiva (sem conhecimento do Fator de Impacto) | F11: SISP – 4.4 Manutenção Corretiva | G11: COR | H11: 0.5 | J11: =SUMIF('Funções'!$D$8:$D$110,G11,'Funções'!$K$8:$K$110) -> 0 | K11: =IF(H11="",COUNTIF('Funções'!D$8:D$110,G11)*I11,H11*J11) -> 0 | L11: =SUMIF('Funções'!$D$8:$D$110,G11,'Funções'!$O$8:$O$110) -> 0 | M11: CORRETIVA
A12: SISP 2.3 | B12: Corretiva (50%) - Fora da garantia (mesma empresa) | F12: SISP – 4.4 Manutenção Corretiva | G12: COR50 | H12: 0.5 | J12: =SUMIF('Funções'!$D$8:$D$110,G12,'Funções'!$K$8:$K$110) -> 0 | K12: =IF(H12="",COUNTIF('Funções'!D$8:D$110,G12)*I12,H12*J12) -> 0 | L12: =SUMIF('Funções'!$D$8:$D$110,G12,'Funções'!$O$8:$O$110) -> 0 | M12: CORRETIVA
